Workbook

Sheet ANAGRAFICA
A1: VERIFICATO | B1: SDO | C1: COGNOME | D1: NOME | E1: ECMO LENS | F1: NUMERO ELSO | G1: ANNO | H1: DN | I1: SEX | J1: DIAGNOSI | K1: POSTCARDIOTOMICO | L1: PESO | M1: ALTEZZA | N1: DATA INGRESSO H | O1: ORA INGRESSO H | P1: DATA INGRESSO ICU | Q1: ORA INGRESSO ICU | S1: NOTE | T1: N RUN | U1: TEL | V1: MAIL | W1: NOTE | X1: CHI HA INSERITO | Z1: CALCOLO ETA | AA1: ANNI
B2: 2123023299 | C2: BEATRICE | D2: GERARDINA | F2: 3272024098 | G2: 2024 | H2: 19354 | I2: F | J2: ECPR IHCA | K2: FALSE | N2: 45291 | O2: 12:00 | P2: 45292 | Q2: 10:40 | T2: 1 | U2: 3460919383 | W2: TEL FRATELLO | X2: DAVIDE | Z2: =DAYS360(H2,N2) -> 25565 | AA2: =Z2/360 -> 71.013889
B3: 2124018611 | C3: CURTO | D3: ROBERTO | G3: 2024 | H3: 23153 | I3: M | J3: FAILURE TO WEAN CPB | K3: TRUE | N3: 45292 | Z3: =DAYS360(H3,N3) -> 21819 | AA3: =Z3/360 -> 60.608333
B4: 2124000149 | C4: MOTTA | D4: FABIO | F4: 3272024051 | G4: 2024 | H4: 22447 | I4: M | J4: FAILURE TO WEAN CPB | K4: TRUE | N4: 45295 | O4: 05:50 | P4: 45295 | Q4: 19:00 | T4: 1 | U4: 3339717409 | W4: FIGLIO MOTTA CLAUDIO | X4: DAVIDE | Z4: =DAYS360(H4,N4) -> 22519 | AA4: =Z4/360 -> 62.552778
B5: 2124000241 | C5: ISELLA | D5: VINCENZO | F5: 3272024052 | G5: 2024 | H5: 21703 | I5: M | J5: ECPR OHCA | K5: FALSE | N5: 45296 | O5: 11:29 | P5: 45296 | Q5: 15:00 | T5: 1 | U5: 3396444336 | W5: sorella | X5: DAVIDE | Z5: =DAYS360(H5,N5) -> 23253 | AA5: =Z5/360 -> 64.591667
B6: 2124000328 | C6: LAVANGA | D6: DONATO | F6: 3272024053 | G6: 2024 | H6: 21957 | I6: M | J6: ECPR OHCA | K6: FALSE | N6: 45298 | O6: 15:25 | P6: 45298 | Q6: 20:00 | T6: 1 | U6: 3294713274 | W6: MOGLIE FRANCA | X6: DAVIDE | Z6: =DAYS360(H6,N6) -> 23006 | AA6: =Z6/360 -> 63.905556
B7: 2124001121 | C7: TIEGHI | D7: MASSIMO | F7: 3272024054 | G7: 2024 | H7: 25745 | I7: M | J7: ECPR IHCA | K7: FALSE | N7: 45309 | O7: 08:42 | P7: 45309 | Q7: 12:00 | T7: 1 | U7: 3479903123 | W7: BARABRA SORELLA | X7: DAVIDE | Z7: =DAYS360(H7,N7) -> 19282 | AA7: =Z7/360 -> 53.561111
B8: 2124002215 | C8: SCHIFANO | D8: FRANCESCO | F8: 3272024055 | G8: 2024 | H8: 22509 | I8: M | J8: ECPR IHCA | K8: FALSE | N8: 45325 | O8: 11:14 | P8: 45325 | Q8: 13:00 | T8: 1 | U8: 3419548554 | W8: moglie | X8: DAVIDE | Z8: =DAYS360(H8,N8) -> 22487 | AA8: =Z8/360 -> 62.463889
B9: 2124202869 | C9: VALSECCHI | D9: ANDREA | F9: 3272024056 | G9: 2024 | H9: 27193 | I9: M | J9: SHOCK CARDIOGENO | K9: TRUE | N9: 45326 | P9: 45327 | Q9: 00:00 | T9: 1 | U9: 3488577020 | W9: fratello | X9: DAVIDE | Z9: =DAYS360(H9,N9) -> 17871 | AA9: =Z9/360 -> 49.641667
B10: 2124003531 | C10: RASPANTI | D10: ANDREA | F10: 3272024057 | G10: 2024 | H10: 29018 | I10: M | J10: SHOCK CARDIOGENO | K10: FALSE | N10: 45343 | O10: 9:50 | P10: 45343 | Q10: 14:00 | T10: 1 | U10: 3497118072 | W10: moglie | X10: DAVIDE | Z10: =DAYS360(H10,N10) -> 16089 | AA10: =Z10/360 -> 44.691667
B11: 2124203781 | C11: CONCA | D11: CAMILLA | F11: 3272024058 | G11: 2024 | H11: 17165 | I11: F | J11: SHOCK CARDIOGENO | K11: TRUE | N11: 45348 | O11: 14:00 | P11: 45348 | Q11: 21:00 | T11: 1 | U11: 3921791959 | W11: FIGLIA | X11: DAVIDE | Z11: =DAYS360(H11,N11) -> 27777 | AA11: =Z11/360 -> 77.158333
B12: 2124003924 | C12: MUHAMMAD | D12: SHARIF | F12: 3272024059 | G12: 2024 | H12: 23633 | I12: M | J12: ECPR OHCA | K12: FALSE | N12: 45349 | O12: 11:25 | P12: 45715 | Q12: 14:00 | T12: 1 | U12: 3274783522 | W12: Moazam | X12: Marta | Z12: =DAYS360(H12,N12) -> 21404 | AA12: =Z12/360 -> 59.455556
B13: 2124004761 | C13: TRAMPOLIN | D13: FABIO | F13: 3272024060 | G13: 2024 | H13: 22735 | I13: M | J13: ECPR OHCA | K13: FALSE | N13: 45361 | O13: 10:13 | P13: 45361 | T13: 1 | U13: 3357216616 | W13: moglie | X13: Marta | Z13: =DAYS360(H13,N13) -> 22300 | AA13: =Z13/360 -> 61.944444
B14: 2124005780 | C14: SAINCIUC | D14: AUREL | F14: 3272024061 | G14: 2024 | H14: 26884 | I14: M | J14: ECPR OHCA | K14: FALSE | N14: 45376 | O14: 03:27 | P14: 45376 | Q14: 06:25 | T14: 1 | X14: nick | Z14: =DAYS360(H14,N14) -> 18227 | AA14: =Z14/360 -> 50.630556
B15: 2124006081 | C15: DOSSI | D15: MAURIZIO ANTONIO | F15: 3272024062 | G15: 2024 | H15: 19741 | I15: M | J15: FAILURE TO WEAN CPB | K15: TRUE | N15: 45379 | O15: 10:00 | P15: 45386 | Q15: 19:30 | T15: 1 | U15: 3384272584 | W15: amico (Davide) | X15: Marta | Z15: =DAYS360(H15,N15) -> 25271 | AA15: =Z15/360 -> 70.197222
B16: 2124007138 | C16: TARTARELLI | D16: GIUSEPPE | F16: 3272024063 | G16: 2024 | H16: 22006 | I16: M | J16: ECPR OHCA | K16: FALSE | N16: 45395 | O16: 11:07 | P16: 45395 | Q16: 13:59 | T16: 1 | X16: nick | Z16: =DAYS360(H16,N16) -> 23053 | AA16: =Z16/360 -> 64.036111
B17: 2124206072 | C17: CONSONNI | D17: GIULIO | F17: 3272024064 | G17: 2024 | H17: 19534 | I17: M | J17: FAILURE TO WEAN CPB | K17: TRUE | N17: 45408 | P17: 45408 | Q17: 19:20 | T17: 2 | X17: nick | Z17: =DAYS360(H17,N17) -> 25502 | AA17: =Z17/360 -> 70.838889
B18: 2124008291 | C18: FUMAGALLI | D18: PIERO | F18: 3272024065 | G18: 2024 | H18: 18074 | I18: M | J18: SHOCK CARDIOGENO | K18: FALSE | N18: 45414 | P18: 45414 | Q18: 10:05 | T18: 1 | X18: ale | Z18: =DAYS360(H18,N18) -> 26947 | AA18: =Z18/360 -> 74.852778
B19: 2124008603 | C19: MARIANI | D19: MARCO | F19: 3272024066 | G19: 2024 | H19: 22576 | J19: INSUFFICIENZA RESPIRATORIA | K19: TRUE | N19: 45419 | O19: 09:00 | P19: 45419 | Q19: 20:49 | U19: 3396748793 | W19: cell moglie | X19: Marta | Z19: =DAYS360(H19,N19) -> 22515 | AA19: =Z19/360 -> 62.541667
B20: 2124009735 | C20: BOSSI | D20: LUDOVICO | E20: 758-1 | F20: 3272024067 | G20: 2024 | H20: 25826 | I20: M | J20: ECPR OHCA | K20: FALSE | N20: 45434 | O20: 23:24 | P20: 45435 | Q20: 02:40 | T20: 1 | X20: nick | Z20: =DAYS360(H20,N20) -> 19327 | AA20: =Z20/360 -> 53.686111
B21: 2124010700 | C21: ORNAGHI | D21: LORENZO | E21: 758-2 | F21: 3272024068 | G21: 2024 | H21: 31213 | I21: M | J21: ECPR OHCA | K21: FALSE | N21: 45448 | O21: 14:36 | P21: 45448 | Q21: 15:50 | T21: 1 | X21: nick | Z21: =DAYS360(H21,N21) -> 14030 | AA21: =Z21/360 -> 38.972222
B22: 2124011236 | C22: BERETTA | D22: ENZO LUCIANO | E22: 758-3 | F22: 3272024069 | G22: 2024 | H22: 20857 | J22: ECPR IHCA | K22: FALSE | N22: 45456 | P22: 45461 | Q22: 22:37 | T22: 1 | U22: 3464994662 | W22: cell moglie | X22: Marta | Z22: =DAYS360(H22,N22) -> 24247 | AA22: =Z22/360 -> 67.352778
B23: 2124011588 | C23: FRATINO | D23: OLIVIERO | E23: 758-4 | F23: 3272024070 | G23: 2024 | H23: 20421 | J23: FAILURE TO WEAN CPB | K23: TRUE | N23: 45462 | O23: 10:00 | P23: 45462 | Q23: 22:39 | T23: 1 | U23: 3472265187 | W23: cell moglie | X23: Marta | Z23: =DAYS360(H23,N23) -> 24681 | AA23: =Z23/360 -> 68.558333
B24: 2124208629 | C24: D'ANDREA | D24: FERNANDO ANTONIO | E24: 758-5 | F24: 3272024071 | G24: 2024 | H24: 20748 | J24: ECPR OHCA | K24: FALSE | N24: 45470 | P24: 45470 | Q24: 20:30 | X24: ale | Z24: =DAYS360(H24,N24) -> 24367 | AA24: =Z24/360 -> 67.686111
B25: 2124208975 | C25: FERRARO | D25: DANIELE | G25: 2024 | H25: 22922 | I25: M | J25: SHOCK CARDIOGENO | K25: TRUE | N25: 45481 | O25: 10:00 | P25: 45481 | Q25: 21:30 | T25: 2 | Z25: =DAYS360(H25,N25) -> 22235 | AA25: =Z25/360 -> 61.763889
B26: 2124012915 | C26: GARGIONI | D26: GIULIO | E26: 758-6 | F26: 3272024072 | G26: 2024 | H26: 26651 | J26: ECPR OHCA | K26: FALSE | N26: 45485 | P26: 26492 | X26: ale | Z26: =DAYS360(H26,N26) -> 18564 | AA26: =Z26/360 -> 51.566667
B27: 2124012963 | C27: TARENZI | D27: GIACOMO | E27: 758-7 | F27: 3272024073 | G27: 2024 | H27: 24708 | I27: M | J27: ECPR IHCA | K27: FALSE | N27: 45487 | O27: 8:54 | P27: 45487 | Q27: 12:00:00 | T27: 1 | U27: 3391624889 | W27: cel moglie | X27: Marta | Z27: =DAYS360(H27,N27) -> 20480 | AA27: =Z27/360 -> 56.888889
B28: 2124013801 | C28: SGOBBA | D28: ANNA | E28: 758-8 | F28: 3272024074 | G28: 2024 | H28: 18724 | I28: F | J28: FAILURE TO WEAN CPB | K28: TRUE | N28: 45502 | P28: 45511 | T28: 1 | X28: ale | Z28: =DAYS360(H28,N28) -> 26393 | AA28: =Z28/360 -> 73.313889
B29: 2124014334 | C29: PONTIGGIA | D29: FLAVIO | E29: 758-9 | F29: 3272024075 | G29: 2024 | H29: 20088 | I29: M | J29: ECPR OHCA | K29: FALSE | N29: 45512 | P29: 45512 | Q29: 13:45 | T29: 1 | X29: Marta | Z29: =DAYS360(H29,N29) -> 25058 | AA29: =Z29/360 -> 69.605556
B30: 2124014461 | C30: FUMAGALLI | D30: LUCA | E30: 758-10 | F30: 3272024076 | G30: 2024 | H30: 27062 | I30: M | J30: SHOCK CARDIOGENO | K30: TRUE | N30: 45515 | P30: 45515 | Q30: 19:00 | T30: 1 | U30: 3299603838 | W30: cell moglie | X30: Marta | Z30: =DAYS360(H30,N30) -> 18189 | AA30: =Z30/360 -> 50.525
B31: 2124015827 | C31: SCHIAVON | D31: ELIO PAOLO | E31: 758-11 | F31: 3272024077 | G31: 2024 | H31: 19537 | I31: M | J31: ECPR IHCA | K31: FALSE | N31: 45543 | O31: 12:00 | P31: 45543 | Q31: 17:23 | T31: 1 | X31: nick | Z31: =DAYS360(H31,N31) -> 25631 | AA31: =Z31/360 -> 71.197222
B32: 2124016781 | C32: TURNO ARTHEMALLE | D32: ALICE | E32: 758-12 | F32: 3272024078 | G32: 2024 | H32: 38392 | I32: F | J32: ECPR IHCA | K32: FALSE | N32: 45557 | P32: 45557 | Q32: 20:00 | T32: 1 | U32: 3899626473 | W32: cell padre | X32: Marta | Z32: =DAYS360(H32,N32) -> 7063 | AA32: =Z32/360 -> 19.619444
B33: 2124211722 | C33: CORIO | D33: GIOVANNI | E33: 758-13 | F33: 3272024079 | G33: 2024 | H33: 19355 | I33: M | J33: SHOCK CARDIOGENO | K33: FALSE | N33: 45570 | P33: 45570 | Q33: 13:30 | T33: 1 | U33: 3397102222 | W33: consenso | X33: Marta | Y33: finire outcome | Z33: =DAYS360(H33,N33) -> 25838 | AA33: =Z33/360 -> 71.772222
B34: 2124017757 | C34: SALA | D34: FELICE | E34: 758-14 | F34: 3272024080 | G34: 2024 | H34: 15908 | I34: M | J34: SHOCK CARDIOGENO | K34: FALSE | N34: 45572 | P34: 45572 | Q34: 17:45 | T34: 1 | U34: 3387481549 | W34: tel figlio | X34: ale | Z34: =DAYS360(H34,N34) -> 29236 | AA34: =Z34/360 -> 81.211111
B35: 2124018637 | C35: CARIBONI | D35: LORENZA | E35: 758-15 | F35: 3272024081 | G35: 2024 | H35: 23512 | I35: F | J35: ECPR OHCA | K35: FALSE | N35: 45584 | P35: 45584 | Q35: 04:30 | T35: 1 | U35: 3352485509 | W35: telefono marito | X35: ale | Z35: =DAYS360(H35,N35) -> 21754 | AA35: =Z35/360 -> 60.427778
B36: 2124018690 | C36: AVENIDO | D36: DELFIN | E36: 758-16 | F36: 3272024082 | G36: 2024 | H36: 22639 | I36: M | J36: ECPR OHCA | K36: FALSE | N36: 45585 | P36: 45585 | Q36: 16:30 | T36: 1 | U36: 3203804205 | W36: telefono moglie | X36: ale | Z36: =DAYS360(H36,N36) -> 22616 | AA36: =Z36/360 -> 62.822222
B37: 2124019184 | C37: SERVIDIO | D37: GIOVANNI | E37: 758-17 | F37: 3272024083 | G37: 2024 | H37: 20145 | I37: M | J37: FAILURE TO WEAN CPB | K37: TRUE | N37: 45593 | P37: 45594 | Q37: 16:30 | T37: 1 | U37: 3334590946 | V37: tel moglie | W37: consenso | X37: ale (manca outcome) | Z37: =DAYS360(H37,N37) -> 25083 | AA37: =Z37/360 -> 69.675
B38: 2124019725 | C38: AMIWO | D38: REX STEVE | E38: 758-18 | F38: 3272024084 | G38: 2024 | H38: 34815 | I38: M | J38: SHOCK CARDIOGENO | K38: FALSE | N38: 45601 | P38: 45601 | Q38: 10:00 | T38: 1 | X38: nick | Z38: =DAYS360(H38,N38) -> 10629 | AA38: =Z38/360 -> 29.525
B39: 2124023603 | C39: MAZZARDIS | D39: DAVIDE | E39: 758-19 | F39: 3272024085 | G39: 2024 | H39: 26916 | I39: M | J39: ECPR OHCA | K39: FALSE | N39: 45622 | P39: 45622 | Q39: 14:30 | T39: 1 | X39: Ale (manca outcome e mobilizzazione max) | Z39: =DAYS360(H39,N39) -> 18437 | AA39: =Z39/360 -> 51.213889
B40: 2124024078 | C40: ROVARIS | D40: ANGELO FELICE | E40: 758-20 | F40: 3272024086 | G40: 2024 | H40: 21280 | I40: M | J40: SHOCK CARDIOGENO | K40: FALSE | N40: 45624 | P40: 45625 | Q40: 00:40 | T40: 1 | Z40: =DAYS360(H40,N40) -> 23993 | AA40: =Z40/360 -> 66.647222
...

Sheet RUN
A1: 18:41 | B1: SDO | C1: COGNOME | D1: NOME | E1: ECMO LENS | F1: ELSO | G1: ANNO | H1: RUN | I1: START DATE | J1: START TIME | K1: END DATE | L1: END TIME | M1: MODE | N1: DATA CONVERSIONE | O1: MODO CONVERSIONE
B2: 2124019725 | C2: =VLOOKUP($B2,ANAGRAFICA!$B$1:$G$306,2,FALSE) -> AMIWO | D2: =VLOOKUP($B2,ANAGRAFICA!$B$1:$G$306,3,FALSE) -> REX STEVE | E2: =VLOOKUP($B2,ANAGRAFICA!$B$1:$G$306,4,FALSE) -> 758-18 | F2: =VLOOKUP($B2,ANAGRAFICA!$B$1:$G$306,5,FALSE) -> 3272024084 | G2: =VLOOKUP($B2,ANAGRAFICA!$B$1:$G$306,6,FALSE) -> 2024 | H2: 1 | I2: 45601 | J2: 07:58 | K2: 45602 | L2: 03:00 | M2: VA
B3: 2125004454 | C3: =VLOOKUP($B3,ANAGRAFICA!$B$1:$G$306,2,FALSE) -> ANTIGNANO | D3: =VLOOKUP($B3,ANAGRAFICA!$B$1:$G$306,3,FALSE) -> MAURO | E3: =VLOOKUP($B3,ANAGRAFICA!$B$1:$G$306,4,FALSE) -> 758-23 | F3: =VLOOKUP($B3,ANAGRAFICA!$B$1:$G$306,5,FALSE) -> 3272025052 | G3: =VLOOKUP($B3,ANAGRAFICA!$B$1:$G$306,6,FALSE) -> 2025 | H3: 1 | I3: 45688 | J3: 02:15 | K3: 45688 | L3: 20:18 | M3: VA
B4: 2124018690 | C4: =VLOOKUP($B4,ANAGRAFICA!$B$1:$G$306,2,FALSE) -> AVENIDO | D4: =VLOOKUP($B4,ANAGRAFICA!$B$1:$G$306,3,FALSE) -> DELFIN | E4: =VLOOKUP($B4,ANAGRAFICA!$B$1:$G$306,4,FALSE) -> 758-16 | F4: =VLOOKUP($B4,ANAGRAFICA!$B$1:$G$306,5,FALSE) -> 3272024082 | G4: =VLOOKUP($B4,ANAGRAFICA!$B$1:$G$306,6,FALSE) -> 2024 | H4: 1 | I4: 45585 | J4: 15:33 | K4: 45590 | L4: 15:33 | M4: VA
B5: 2123023299 | C5: =VLOOKUP($B5,ANAGRAFICA!$B$1:$G$306,2,FALSE) -> BEATRICE | D5: =VLOOKUP($B5,ANAGRAFICA!$B$1:$G$306,3,FALSE) -> GERARDINA | E5: =VLOOKUP($B5,ANAGRAFICA!$B$1:$G$306,4,FALSE) | F5: =VLOOKUP($B5,ANAGRAFICA!$B$1:$G$306,5,FALSE) -> 3272024098 | G5: =VLOOKUP($B5,ANAGRAFICA!$B$1:$G$306,6,FALSE) -> 2024 | H5: 1 | I5: 45292 | J5: 23:50:00 | K5: 45293 | L5: 07:25:00 | M5: VA
B6: 2124011236 | C6: =VLOOKUP($B6,ANAGRAFICA!$B$1:$G$306,2,FALSE) -> BERETTA | D6: =VLOOKUP($B6,ANAGRAFICA!$B$1:$G$306,3,FALSE) -> ENZO LUCIANO | E6: =VLOOKUP($B6,ANAGRAFICA!$B$1:$G$306,4,FALSE) -> 758-3 | F6: =VLOOKUP($B6,ANAGRAFICA!$B$1:$G$306,5,FALSE) -> 3272024069 | G6: =VLOOKUP($B6,ANAGRAFICA!$B$1:$G$306,6,FALSE) -> 2024 | H6: 1 | I6: 45461 | J6: 21:10 | K6: 45474 | L6: 11:30 | M6: VA
B7: 2124009735 | C7: =VLOOKUP($B7,ANAGRAFICA!$B$1:$G$306,2,FALSE) -> BOSSI | D7: =VLOOKUP($B7,ANAGRAFICA!$B$1:$G$306,3,FALSE) -> LUDOVICO | E7: =VLOOKUP($B7,ANAGRAFICA!$B$1:$G$306,4,FALSE) -> 758-1 | F7: =VLOOKUP($B7,ANAGRAFICA!$B$1:$G$306,5,FALSE) -> 3272024067 | G7: =VLOOKUP($B7,ANAGRAFICA!$B$1:$G$306,6,FALSE) -> 2024 | H7: 1 | I7: 45434 | J7: 23:32 | K7: 45440 | L7: 16:44 | M7: VA
B8: 2124018637 | C8: =VLOOKUP($B8,ANAGRAFICA!$B$1:$G$306,2,FALSE) -> CARIBONI | D8: =VLOOKUP($B8,ANAGRAFICA!$B$1:$G$306,3,FALSE) -> LORENZA | E8: =VLOOKUP($B8,ANAGRAFICA!$B$1:$G$306,4,FALSE) -> 758-15 | F8: =VLOOKUP($B8,ANAGRAFICA!$B$1:$G$306,5,FALSE) -> 3272024081 | G8: =VLOOKUP($B8,ANAGRAFICA!$B$1:$G$306,6,FALSE) -> 2024 | H8: 1 | I8: 45584 | J8: 03:04 | K8: 45585 | L8: 10:50 | M8: VA
B9: 2124203781 | C9: =VLOOKUP($B9,ANAGRAFICA!$B$1:$G$306,2,FALSE) -> CONCA | D9: =VLOOKUP($B9,ANAGRAFICA!$B$1:$G$306,3,FALSE) -> CAMILLA | E9: =VLOOKUP($B9,ANAGRAFICA!$B$1:$G$306,4,FALSE) | F9: =VLOOKUP($B9,ANAGRAFICA!$B$1:$G$306,5,FALSE) -> 3272024058 | G9: =VLOOKUP($B9,ANAGRAFICA!$B$1:$G$306,6,FALSE) -> 2024 | H9: 1 | I9: 45351 | J9: 12:50 | K9: 45352 | L9: 12:00 | M9: VA
B10: 2124206072 | C10: =VLOOKUP($B10,ANAGRAFICA!$B$1:$G$306,2,FALSE) -> CONSONNI | D10: =VLOOKUP($B10,ANAGRAFICA!$B$1:$G$306,3,FALSE) -> GIULIO | E10: =VLOOKUP($B10,ANAGRAFICA!$B$1:$G$306,4,FALSE) | F10: =VLOOKUP($B10,ANAGRAFICA!$B$1:$G$306,5,FALSE) -> 3272024064 | G10: =VLOOKUP($B10,ANAGRAFICA!$B$1:$G$306,6,FALSE) -> 2024 | H10: 1 | I10: 45409 | J10: 00:07 | K10: 45414 | L10: 11:10 | M10: VA
B11: 2124206072 | C11: =VLOOKUP($B11,ANAGRAFICA!$B$1:$G$306,2,FALSE) -> CONSONNI | D11: =VLOOKUP($B11,ANAGRAFICA!$B$1:$G$306,3,FALSE) -> GIULIO | E11: =VLOOKUP($B11,ANAGRAFICA!$B$1:$G$306,4,FALSE) | F11: =VLOOKUP($B11,ANAGRAFICA!$B$1:$G$306,5,FALSE) -> 3272024064 | G11: =VLOOKUP($B11,ANAGRAFICA!$B$1:$G$306,6,FALSE) -> 2024 | H11: 2 | I11: 45416 | J11: 02:15 | K11: 45417 | L11: 13:30 | M11: VA
B12: 2124211722 | C12: =VLOOKUP($B12,ANAGRAFICA!$B$1:$G$306,2,FALSE) -> CORIO | D12: =VLOOKUP($B12,ANAGRAFICA!$B$1:$G$306,3,FALSE) -> GIOVANNI | E12: =VLOOKUP($B12,ANAGRAFICA!$B$1:$G$306,4,FALSE) -> 758-13 | F12: =VLOOKUP($B12,ANAGRAFICA!$B$1:$G$306,5,FALSE) -> 3272024079 | G12: =VLOOKUP($B12,ANAGRAFICA!$B$1:$G$306,6,FALSE) -> 2024 | H12: 1 | I12: 45571 | J12: 20:28 | K12: 45576 | L12: 17:00 | M12: VA
B13: 2124018611 | C13: =VLOOKUP($B13,ANAGRAFICA!$B$1:$G$306,2,FALSE) -> CURTO | D13: =VLOOKUP($B13,ANAGRAFICA!$B$1:$G$306,3,FALSE) -> ROBERTO | E13: =VLOOKUP($B13,ANAGRAFICA!$B$1:$G$306,4,FALSE) | F13: =VLOOKUP($B13,ANAGRAFICA!$B$1:$G$306,5,FALSE) | G13: =VLOOKUP($B13,ANAGRAFICA!$B$1:$G$306,6,FALSE) -> 2024 | H13: 1 | I13: 45583 | J13: 22:36 | K13: 45586 | L13: 13:05 | M13: VA
... B22: 2124000241 | C22: =VLOOKUP($B22,ANAGRAFICA!$B$1:$G$306,2,FALSE) -> ISELLA | D22: =VLOOKUP($B22,ANAGRAFICA!$B$1:$G$306,3,FALSE) -> VINCENZO | E22: =VLOOKUP($B22,ANAGRAFICA!$B$1:$G$306,4,FALSE) | F22: =VLOOKUP($B22,ANAGRAFICA!$B$1:$G$306,5,FALSE) -> 3272024052 | G22: =VLOOKUP($B22,ANAGRAFICA!$B$1:$G$306,6,FALSE) -> 2024 | H22: 1 | I22: 45296 | J22: 11:53 | K22: 45297 | L22: 09:00 | M22: VA
B23: 2124000328 | C23: =VLOOKUP($B23,ANAGRAFICA!$B$1:$G$306,2,FALSE) -> LAVANGA | D23: =VLOOKUP($B23,ANAGRAFICA!$B$1:$G$306,3,FALSE) -> DONATO | E23: =VLOOKUP($B23,ANAGRAFICA!$B$1:$G$306,4,FALSE) | F23: =VLOOKUP($B23,ANAGRAFICA!$B$1:$G$306,5,FALSE) -> 3272024053 | G23: =VLOOKUP($B23,ANAGRAFICA!$B$1:$G$306,6,FALSE) -> 2024 | H23: 1 | I23: 45298 | J23: 15:35 | K23: 45301 | L23: 0 | M23: VA
B24: 2125004867 | C24: =VLOOKUP($B24,ANAGRAFICA!$B$1:$G$306,2,FALSE) -> MARCONI | D24: =VLOOKUP($B24,ANAGRAFICA!$B$1:$G$306,3,FALSE) -> PIETRO VITTORIO | E24: =VLOOKUP($B24,ANAGRAFICA!$B$1:$G$306,4,FALSE) | F24: =VLOOKUP($B24,ANAGRAFICA!$B$1:$G$306,5,FALSE) -> 3272025053 | G24: =VLOOKUP($B24,ANAGRAFICA!$B$1:$G$306,6,FALSE) -> 2025 | H24: 1 | I24: 45691 | J24: 11:53 | K24: 45692 | L24: 17:04 | M24: VA
B25: 2124008603 | C25: =VLOOKUP($B25,ANAGRAFICA!$B$1:$G$306,2,FALSE) -> MARIANI | D25: =VLOOKUP($B25,ANAGRAFICA!$B$1:$G$306,3,FALSE) -> MARCO | E25: =VLOOKUP($B25,ANAGRAFICA!$B$1:$G$306,4,FALSE) | F25: =VLOOKUP($B25,ANAGRAFICA!$B$1:$G$306,5,FALSE) -> 3272024066 | G25: =VLOOKUP($B25,ANAGRAFICA!$B$1:$G$306,6,FALSE) -> 2024 | H25: 1 | I25: 45425 | J25: 13:28 | K25: 45447 | L25: 15:30 | M25: VV
B26: 2124023603 | C26: =VLOOKUP($B26,ANAGRAFICA!$B$1:$G$306,2,FALSE) -> MAZZARDIS | D26: =VLOOKUP($B26,ANAGRAFICA!$B$1:$G$306,3,FALSE) -> DAVIDE | E26: =VLOOKUP($B26,ANAGRAFICA!$B$1:$G$306,4,FALSE) -> 758-19 | F26: =VLOOKUP($B26,ANAGRAFICA!$B$1:$G$306,5,FALSE) -> 3272024085 | G26: =VLOOKUP($B26,ANAGRAFICA!$B$1:$G$306,6,FALSE) -> 2024 | H26: 1 | I26: 45622 | J26: 12:06 | K26: 45627 | L26: 15:30 | M26: VA
B27: 2124023603 | C27: =VLOOKUP($B27,ANAGRAFICA!$B$1:$G$306,2,FALSE) -> MAZZARDIS | D27: =VLOOKUP($B27,ANAGRAFICA!$B$1:$G$306,3,FALSE) -> DAVIDE | E27: =VLOOKUP($B27,ANAGRAFICA!$B$1:$G$306,4,FALSE) -> 758-19 | F27: =VLOOKUP($B27,ANAGRAFICA!$B$1:$G$306,5,FALSE) -> 3272024085 | G27: =VLOOKUP($B27,ANAGRAFICA!$B$1:$G$306,6,FALSE) -> 2024 | H27: 2 | I27: 45641 | J27: 06:00 | K27: 45657 | L27: 09:40 | M27: VA
B28: 2124000149 | C28: =VLOOKUP($B28,ANAGRAFICA!$B$1:$G$306,2,FALSE) -> MOTTA | D28: =VLOOKUP($B28,ANAGRAFICA!$B$1:$G$306,3,FALSE) -> FABIO | E28: =VLOOKUP($B28,ANAGRAFICA!$B$1:$G$306,4,FALSE) | F28: =VLOOKUP($B28,ANAGRAFICA!$B$1:$G$306,5,FALSE) -> 3272024051 | G28: =VLOOKUP($B28,ANAGRAFICA!$B$1:$G$306,6,FALSE) -> 2024 | H28: 1 | I28: 45295 | J28: 15:55 | K28: 45299 | L28: 13:30 | M28: VA
B29: 2124003924 | C29: =VLOOKUP($B29,ANAGRAFICA!$B$1:$G$306,2,FALSE) -> MUHAMMAD | D29: =VLOOKUP($B29,ANAGRAFICA!$B$1:$G$306,3,FALSE) -> SHARIF | E29: =VLOOKUP($B29,ANAGRAFICA!$B$1:$G$306,4,FALSE) | F29: =VLOOKUP($B29,ANAGRAFICA!$B$1:$G$306,5,FALSE) -> 3272024059 | G29: =VLOOKUP($B29,ANAGRAFICA!$B$1:$G$306,6,FALSE) -> 2024 | H29: 1 | I29: 45349 | J29: 11:39 | K29: 45350 | L29: 15:40 | M29: VA
B30: 2124010700 | C30: =VLOOKUP($B30,ANAGRAFICA!$B$1:$G$306,2,FALSE) -> ORNAGHI | D30: =VLOOKUP($B30,ANAGRAFICA!$B$1:$G$306,3,FALSE) -> LORENZO | E30: =VLOOKUP($B30,ANAGRAFICA!$B$1:$G$306,4,FALSE) -> 758-2 | F30: =VLOOKUP($B30,ANAGRAFICA!$B$1:$G$306,5,FALSE) -> 3272024068 | G30: =VLOOKUP($B30,ANAGRAFICA!$B$1:$G$306,6,FALSE) -> 2024 | H30: 1 | I30: 45448 | J30: 14:47 | K30: 45450 | L30: 10:15 | M30: VA
B31: 2124025878 | C31: =VLOOKUP($B31,ANAGRAFICA!$B$1:$G$306,2,FALSE) -> PEDRONI | D31: =VLOOKUP($B31,ANAGRAFICA!$B$1:$G$306,3,FALSE) -> PIERANGELO | E31: =VLOOKUP($B31,ANAGRAFICA!$B$1:$G$306,4,FALSE) -> 758-22 | F31: =VLOOKUP($B31,ANAGRAFICA!$B$1:$G$306,5,FALSE) -> 3272024088 | G31: =VLOOKUP($B31,ANAGRAFICA!$B$1:$G$306,6,FALSE) -> 2024 | H31: 1 | I31: 45636 | J31: 20:10 | K31: 19/12/ 2024 | L31: 16:10 | M31: VA
B32: 2124014334 | C32: =VLOOKUP($B32,ANAGRAFICA!$B$1:$G$306,2,FALSE) -> PONTIGGIA | D32: =VLOOKUP($B32,ANAGRAFICA!$B$1:$G$306,3,FALSE) -> FLAVIO | E32: =VLOOKUP($B32,ANAGRAFICA!$B$1:$G$306,4,FALSE) -> 758-9 | F32: =VLOOKUP($B32,ANAGRAFICA!$B$1:$G$306,5,FALSE) -> 3272024075 | G32: =VLOOKUP($B32,ANAGRAFICA!$B$1:$G$306,6,FALSE) -> 2024 | H32: 1 | I32: 45512 | J32: 11:42 | K32: 45513 | L32: 18:55 | M32: VA
B33: 2124003531 | C33: =VLOOKUP($B33,ANAGRAFICA!$B$1:$G$306,2,FALSE) -> RASPANTI | D33: =VLOOKUP($B33,ANAGRAFICA!$B$1:$G$306,3,FALSE) -> ANDREA | E33: =VLOOKUP($B33,ANAGRAFICA!$B$1:$G$306,4,FALSE) | F33: =VLOOKUP($B33,ANAGRAFICA!$B$1:$G$306,5,FALSE) -> 3272024057 | G33: =VLOOKUP($B33,ANAGRAFICA!$B$1:$G$306,6,FALSE) -> 2024 | H33: 1 | I33: 45343 | J33: 18:05 | K33: 45351 | L33: 12:00 | M33: va
B34: 2124024078 | C34: =VLOOKUP($B34,ANAGRAFICA!$B$1:$G$306,2,FALSE) -> ROVARIS | D34: =VLOOKUP($B34,ANAGRAFICA!$B$1:$G$306,3,FALSE) -> ANGELO FELICE | E34: =VLOOKUP($B34,ANAGRAFICA!$B$1:$G$306,4,FALSE) -> 758-20 | F34: =VLOOKUP($B34,ANAGRAFICA!$B$1:$G$306,5,FALSE) -> 3272024086 | G34: =VLOOKUP($B34,ANAGRAFICA!$B$1:$G$306,6,FALSE) -> 2024 | H34: 1 | I34: 45625 | J34: 19:50 | K34: 45632 | L34: 14:00 | M34: VA
B35: 2124005780 | C35: =VLOOKUP($B35,ANAGRAFICA!$B$1:$G$306,2,FALSE) -> SAINCIUC | D35: =VLOOKUP($B35,ANAGRAFICA!$B$1:$G$306,3,FALSE) -> AUREL | E35: =VLOOKUP($B35,ANAGRAFICA!$B$1:$G$306,4,FALSE) | F35: =VLOOKUP($B35,ANAGRAFICA!$B$1:$G$306,5,FALSE) -> 3272024061 | G35: =VLOOKUP($B35,ANAGRAFICA!$B$1:$G$306,6,FALSE) -> 2024 | H35: 1 | I35: 45376 | J35: 03:45 | K35: 45378 | L35: 04:46 | M35: VA
B36: 2124017757 | C36: =VLOOKUP($B36,ANAGRAFICA!$B$1:$G$306,2,FALSE) -> SALA | D36: =VLOOKUP($B36,ANAGRAFICA!$B$1:$G$306,3,FALSE) -> FELICE | E36: =VLOOKUP($B36,ANAGRAFICA!$B$1:$G$306,4,FALSE) -> 758-14 | F36: =VLOOKUP($B36,ANAGRAFICA!$B$1:$G$306,5,FALSE) -> 3272024080 | G36: =VLOOKUP($B36,ANAGRAFICA!$B$1:$G$306,6,FALSE) -> 2024 | H36: 1 | I36: 45572 | J36: 08:15 | K36: 45576 | L36: 13:45 | M36: VA
B37: 2124015827 | C37: =VLOOKUP($B37,ANAGRAFICA!$B$1:$G$306,2,FALSE) -> SCHIAVON | D37: =VLOOKUP($B37,ANAGRAFICA!$B$1:$G$306,3,FALSE) -> ELIO PAOLO | E37: =VLOOKUP($B37,ANAGRAFICA!$B$1:$G$306,4,FALSE) -> 758-11 | F37: =VLOOKUP($B37,ANAGRAFICA!$B$1:$G$306,5,FALSE) -> 3272024077 | G37: =VLOOKUP($B37,ANAGRAFICA!$B$1:$G$306,6,FALSE) -> 2024 | H37: 1 | I37: 45543 | J37: 16:55 | K37: 45547 | L37: 10:00 | M37: VA
B38: 2124002215 | C38: =VLOOKUP($B38,ANAGRAFICA!$B$1:$G$306,2,FALSE) -> SCHIFANO | D38: =VLOOKUP($B38,ANAGRAFICA!$B$1:$G$306,3,FALSE) -> FRANCESCO | E38: =VLOOKUP($B38,ANAGRAFICA!$B$1:$G$306,4,FALSE) | F38: =VLOOKUP($B38,ANAGRAFICA!$B$1:$G$306,5,FALSE) -> 3272024055 | G38: =VLOOKUP($B38,ANAGRAFICA!$B$1:$G$306,6,FALSE) -> 2024 | H38: 1 | I38: 45325 | J38: 13:45 | K38: 45329 | L38: 13:00 | M38: va
B39: 2124019184 | C39: =VLOOKUP($B39,ANAGRAFICA!$B$1:$G$306,2,FALSE) -> SERVIDIO | D39: =VLOOKUP($B39,ANAGRAFICA!$B$1:$G$306,3,FALSE) -> GIOVANNI | E39: =VLOOKUP($B39,ANAGRAFICA!$B$1:$G$306,4,FALSE) -> 758-17 | F39: =VLOOKUP($B39,ANAGRAFICA!$B$1:$G$306,5,FALSE) -> 3272024083 | G39: =VLOOKUP($B39,ANAGRAFICA!$B$1:$G$306,6,FALSE) -> 2024 | H39: 1 | I39: 45594 | J39: 16:30 | K39: 45611 | L39: 11:00 | M39: VA
B40: 2124013801 | C40: =VLOOKUP($B40,ANAGRAFICA!$B$1:$G$306,2,FALSE) -> SGOBBA | D40: =VLOOKUP($B40,ANAGRAFICA!$B$1:$G$306,3,FALSE) -> ANNA | E40: =VLOOKUP($B40,ANAGRAFICA!$B$1:$G$306,4,FALSE) -> 758-8 | F40: =VLOOKUP($B40,ANAGRAFICA!$B$1:$G$306,5,FALSE) -> 3272024074 | G40: =VLOOKUP($B40,ANAGRAFICA!$B$1:$G$306,6,FALSE) -> 2024 | H40: 1 | I40: 45511 | J40: 15:30 | K40: 45520 | L40: 18:00 | M40: VA
B41: 2125000348 | C41: =VLOOKUP($B41,ANAGRAFICA!$B$1:$G$306,2,FALSE) -> SLAVKOVA | D41: =VLOOKUP($B41,ANAGRAFICA!$B$1:$G$306,3,FALSE) -> EVELINA PLAMENOVA | E41: =VLOOKUP($B41,ANAGRAFICA!$B$1:$G$306,4,FALSE) | F41: =VLOOKUP($B41,ANAGRAFICA!$B$1:$G$306,5,FALSE) -> 3272025051 | G41: =VLOOKUP($B41,ANAGRAFICA!$B$1:$G$306,6,FALSE) -> 2025 | H41: 1 | I41: 45662 | J41: 22:35 | K41: 45665 | L41: 3:00 | M41: VA | P41: decesso 07/01/2025 10:52
B42: 2124012963 | C42: =VLOOKUP($B42,ANAGRAFICA!$B$1:$G$306,2,FALSE) -> TARENZI | D42: =VLOOKUP($B42,ANAGRAFICA!$B$1:$G$306,3,FALSE) -> GIACOMO | E42: =VLOOKUP($B42,ANAGRAFICA!$B$1:$G$306,4,FALSE) -> 758-7 | F42: =VLOOKUP($B42,ANAGRAFICA!$B$1:$G$306,5,FALSE) -> 3272024073 | G42: =VLOOKUP($B42,ANAGRAFICA!$B$1:$G$306,6,FALSE) -> 2024 | H42: 1 | I42: 45487 | J42: 09:23:00 | K42: 45496 | L42: 11:53 | M42: VA | N42: . | O42: . | P42: .
B43: 2124012963 | C43: =VLOOKUP($B43,ANAGRAFICA!$B$1:$G$306,2,FALSE) -> TARENZI | D43: =VLOOKUP($B43,ANAGRAFICA!$B$1:$G$306,3,FALSE) -> GIACOMO | E43: =VLOOKUP($B43,ANAGRAFICA!$B$1:$G$306,4,FALSE) -> 758-7 | F43: =VLOOKUP($B43,ANAGRAFICA!$B$1:$G$306,5,FALSE) -> 3272024073 | G43: =VLOOKUP($B43,ANAGRAFICA!$B$1:$G$306,6,FALSE) -> 2024 | H43: 1 | I43: 45487 | J43: 09:23 | K43: 45496 | L43: 11:53 | M43: VA
B44: 2124007138 | C44: =VLOOKUP($B44,ANAGRAFICA!$B$1:$G$306,2,FALSE) -> TARTARELLI | D44: =VLOOKUP($B44,ANAGRAFICA!$B$1:$G$306,3,FALSE) -> GIUSEPPE | E44: =VLOOKUP($B44,ANAGRAFICA!$B$1:$G$306,4,FALSE) | F44: =VLOOKUP($B44,ANAGRAFICA!$B$1:$G$306,5,FALSE) -> 3272024063 | G44: =VLOOKUP($B44,ANAGRAFICA!$B$1:$G$306,6,FALSE) -> 2024 | H44: 1 | I44: 45395 | J44: 12:02 | K44: 45397 | L44: 21:20 | M44: VA
B45: 2124001121 | C45: =VLOOKUP($B45,ANAGRAFICA!$B$1:$G$306,2,FALSE) -> TIEGHI | D45: =VLOOKUP($B45,ANAGRAFICA!$B$1:$G$306,3,FALSE) -> MASSIMO | E45: =VLOOKUP($B45,ANAGRAFICA!$B$1:$G$306,4,FALSE) | F45: =VLOOKUP($B45,ANAGRAFICA!$B$1:$G$306,5,FALSE) -> 3272024054 | G45: =VLOOKUP($B45,ANAGRAFICA!$B$1:$G$306,6,FALSE) -> 2024 | H45: 1 | I45: 45309 | J45: 09:30 | K45: 45310 | L45: 18:00 | M45: VA
B46: 2124004761 | C46: =VLOOKUP($B46,ANAGRAFICA!$B$1:$G$306,2,FALSE) -> TRAMPOLIN | D46: =VLOOKUP($B46,ANAGRAFICA!$B$1:$G$306,3,FALSE) -> FABIO | E46: =VLOOKUP($B46,ANAGRAFICA!$B$1:$G$306,4,FALSE) | F46: =VLOOKUP($B46,ANAGRAFICA!$B$1:$G$306,5,FALSE) -> 3272024060 | G46: =VLOOKUP($B46,ANAGRAFICA!$B$1:$G$306,6,FALSE) -> 2024 | H46: 1 | I46: 45361 | J46: 10:25 | K46: 45363 | L46: 14:15 | M46: VA
B47: 2124016781 | C47: =VLOOKUP($B47,ANAGRAFICA!$B$1:$G$306,2,FALSE) -> TURNO ARTHEMALLE | D47: =VLOOKUP($B47,ANAGRAFICA!$B$1:$G$306,3,FALSE) -> ALICE | E47: =VLOOKUP($B47,ANAGRAFICA!$B$1:$G$306,4,FALSE) -> 758-12 | F47: =VLOOKUP($B47,ANAGRAFICA!$B$1:$G$306,5,FALSE) -> 3272024078 | G47: =VLOOKUP($B47,ANAGRAFICA!$B$1:$G$306,6,FALSE) -> 2024 | H47: 1 | I47: 45561 | J47: 14:00 | K47: 45566 | L47: 10:30 | M47: VA
B48: 2124202869 | C48: =VLOOKUP($B48,ANAGRAFICA!$B$1:$G$306,2,FALSE) -> VALSECCHI | D48: =VLOOKUP($B48,ANAGRAFICA!$B$1:$G$306,3,FALSE) -> ANDREA | E48: =VLOOKUP($B48,ANAGRAFICA!$B$1:$G$306,4,FALSE) | F48: =VLOOKUP($B48,ANAGRAFICA!$B$1:$G$306,5,FALSE) -> 3272024056 | G48: =VLOOKUP($B48,ANAGRAFICA!$B$1:$G$306,6,FALSE) -> 2024 | H48: 1 | I48: 45336 | J48: 18:44 | K48: 45342 | L48: 12:00 | M48: va
...

Sheet EQUIPMENT
A1: SDO | B1: COGNOME | C1: NOME | D1: ECMO LENS | E1: ELSO | F1: ANNO | G1: RUN | H1: CIRCUIT N° | I1: START DATE | J1: START TIME | K1: END DATE | L1: END TIME | M1: HEAT EXCHANGER | N1: MEMBRAN LUNG | O1: PUMP | P1: REASON FOR CHANGE
A2: 2124019725 | B2: =VLOOKUP($A2,ANAGRAFICA!$B$1:$G$306,2,FALSE) -> AMIWO | C2: =VLOOKUP($A2,ANAGRAFICA!$B$1:$G$306,3,FALSE) -> REX STEVE | D2: =VLOOKUP($A2,ANAGRAFICA!$B$1:$G$306,4,FALSE) -> 758-18 | E2: =VLOOKUP($A2,ANAGRAFICA!$B$1:$G$306,5,FALSE) -> 3272024084 | F2: =VLOOKUP($A2,ANAGRAFICA!$B$1:$G$306,6,FALSE) -> 2024 | G2: 1 | H2: 1 | I2: 45601 | J2: 07:58 | K2: 45602 | L2: 03:00 | M2: GETINGE HU35 | N2: GETINGE PLS SET | O2: PLS
A3: 2124018690 | B3: =VLOOKUP($A3,ANAGRAFICA!$B$1:$G$306,2,FALSE) -> AVENIDO | C3: =VLOOKUP($A3,ANAGRAFICA!$B$1:$G$306,3,FALSE) -> DELFIN | D3: =VLOOKUP($A3,ANAGRAFICA!$B$1:$G$306,4,FALSE) -> 758-16 | E3: =VLOOKUP($A3,ANAGRAFICA!$B$1:$G$306,5,FALSE) -> 3272024082 | F3: =VLOOKUP($A3,ANAGRAFICA!$B$1:$G$306,6,FALSE) -> 2024 | G3: 1 | H3: 1 | I3: 45585 | J3: 15:33 | K3: 45590 | L3: 15:33 | M3: GETINGE HU35 | N3: GETINGE HLS SET | O3: HLS
A4: 2123023299 | B4: =VLOOKUP($A4,ANAGRAFICA!$B$1:$G$306,2,FALSE) -> BEATRICE | C4: =VLOOKUP($A4,ANAGRAFICA!$B$1:$G$306,3,FALSE) -> GERARDINA | D4: =VLOOKUP($A4,ANAGRAFICA!$B$1:$G$306,4,FALSE) | E4: =VLOOKUP($A4,ANAGRAFICA!$B$1:$G$306,5,FALSE) -> 3272024098 | F4: =VLOOKUP($A4,ANAGRAFICA!$B$1:$G$306,6,FALSE) -> 2024 | G4: 1 | H4: 1 | I4: 45292 | J4: 23:50:00 | K4: 45293 | L4: 07:25:00 | M4: GETINGE HU35 | N4: GETINGE PLS SET | O4: PLS
A5: 2124011236 | B5: =VLOOKUP($A5,ANAGRAFICA!$B$1:$G$306,2,FALSE) -> BERETTA | C5: =VLOOKUP($A5,ANAGRAFICA!$B$1:$G$306,3,FALSE) -> ENZO LUCIANO | D5: =VLOOKUP($A5,ANAGRAFICA!$B$1:$G$306,4,FALSE) -> 758-3 | E5: =VLOOKUP($A5,ANAGRAFICA!$B$1:$G$306,5,FALSE) -> 3272024069 | F5: =VLOOKUP($A5,ANAGRAFICA!$B$1:$G$306,6,FALSE) -> 2024 | G5: 1 | H5: 1 | I5: 45461 | J5: 21:10 | K5: 45474 | L5: 11:30 | M5: GETINGE HU35 | N5: GETINGE PLS SET | O5: PLS
A6: 2124009735 | B6: =VLOOKUP($A6,ANAGRAFICA!$B$1:$G$306,2,FALSE) -> BOSSI | C6: =VLOOKUP($A6,ANAGRAFICA!$B$1:$G$306,3,FALSE) -> LUDOVICO | D6: =VLOOKUP($A6,ANAGRAFICA!$B$1:$G$306,4,FALSE) -> 758-1 | E6: =VLOOKUP($A6,ANAGRAFICA!$B$1:$G$306,5,FALSE) -> 3272024067 | F6: =VLOOKUP($A6,ANAGRAFICA!$B$1:$G$306,6,FALSE) -> 2024 | G6: 1 | H6: 1 | I6: 45435 | J6: 23:32 | K6: 45440 | L6: 16:44 | M6: GETINGE HU35 | N6: GETINGE PLS SET | O6: PLS
A7: 2124018637 | B7: =VLOOKUP($A7,ANAGRAFICA!$B$1:$G$306,2,FALSE) -> CARIBONI | C7: =VLOOKUP($A7,ANAGRAFICA!$B$1:$G$306,3,FALSE) -> LORENZA | D7: =VLOOKUP($A7,ANAGRAFICA!$B$1:$G$306,4,FALSE) -> 758-15 | E7: =VLOOKUP($A7,ANAGRAFICA!$B$1:$G$306,5,FALSE) -> 3272024081 | F7: =VLOOKUP($A7,ANAGRAFICA!$B$1:$G$306,6,FALSE) -> 2024 | G7: 1 | H7: 1 | I7: 45584 | J7: 03:04 | K7: 45585 | L7: 10:50 | M7: GETINGE HU35 | N7: GETINGE PLS SET | O7: PLS
A8: 2124203781 | B8: =VLOOKUP($A8,ANAGRAFICA!$B$1:$G$306,2,FALSE) -> CONCA | C8: =VLOOKUP($A8,ANAGRAFICA!$B$1:$G$306,3,FALSE) -> CAMILLA | D8: =VLOOKUP($A8,ANAGRAFICA!$B$1:$G$306,4,FALSE) | E8: =VLOOKUP($A8,ANAGRAFICA!$B$1:$G$306,5,FALSE) -> 3272024058 | F8: =VLOOKUP($A8,ANAGRAFICA!$B$1:$G$306,6,FALSE) -> 2024 | G8: 1 | H8: 1 | I8: 45351 | J8: 12:50 | K8: 45352 | L8: 12:00 | M8: GETINGE HU35 | N8: GETINGE PLS SET | O8: PLS
A9: 2124206072 | B9: =VLOOKUP($A9,ANAGRAFICA!$B$1:$G$306,2,FALSE) -> CONSONNI | C9: =VLOOKUP($A9,ANAGRAFICA!$B$1:$G$306,3,FALSE) -> GIULIO | D9: =VLOOKUP($A9,ANAGRAFICA!$B$1:$G$306,4,FALSE) | E9: =VLOOKUP($A9,ANAGRAFICA!$B$1:$G$306,5,FALSE) -> 3272024064 | F9: =VLOOKUP($A9,ANAGRAFICA!$B$1:$G$306,6,FALSE) -> 2024 | G9: 1 | H9: 1 | I9: 45409 | J9: 00:07 | K9: 45414 | L9: 11:10 | M9: GETINGE HU35 | N9: GETINGE PLS SET | O9: PLS
A10: 2124206072 | B10: =VLOOKUP($A10,ANAGRAFICA!$B$1:$G$306,2,FALSE) -> CONSONNI | C10: =VLOOKUP($A10,ANAGRAFICA!$B$1:$G$306,3,FALSE) -> GIULIO | D10: =VLOOKUP($A10,ANAGRAFICA!$B$1:$G$306,4,FALSE) | E10: =VLOOKUP($A10,ANAGRAFICA!$B$1:$G$306,5,FALSE) -> 3272024064 | F10: =VLOOKUP($A10,ANAGRAFICA!$B$1:$G$306,6,FALSE) -> 2024 | G10: 2 | H10: 1 | I10: 45414 | J10: 02:15 | K10: 45417 | L10: 13:30 | M10: GETINGE HU35 | N10: GETINGE PLS SET | O10: PLS
A11: 2124211722 | B11: =VLOOKUP($A11,ANAGRAFICA!$B$1:$G$306,2,FALSE) -> CORIO | C11: =VLOOKUP($A11,ANAGRAFICA!$B$1:$G$306,3,FALSE) -> GIOVANNI | D11: =VLOOKUP($A11,ANAGRAFICA!$B$1:$G$306,4,FALSE) -> 758-13 | E11: =VLOOKUP($A11,ANAGRAFICA!$B$1:$G$306,5,FALSE) -> 3272024079 | F11: =VLOOKUP($A11,ANAGRAFICA!$B$1:$G$306,6,FALSE) -> 2024 | G11: 1 | H11: 1 | I11: 45571 | J11: 20:28 | K11: 45576 | L11: 17:00 | M11: GETINGE HU35 | N11: GETINGE PLS SET | O11: PLS
A12: 2124018611 | B12: =VLOOKUP($A12,ANAGRAFICA!$B$1:$G$306,2,FALSE) -> CURTO | C12: =VLOOKUP($A12,ANAGRAFICA!$B$1:$G$306,3,FALSE) -> ROBERTO | D12: =VLOOKUP($A12,ANAGRAFICA!$B$1:$G$306,4,FALSE) | E12: =VLOOKUP($A12,ANAGRAFICA!$B$1:$G$306,5,FALSE) | F12: =VLOOKUP($A12,ANAGRAFICA!$B$1:$G$306,6,FALSE) -> 2024 | H12: 1 | I12: 45583 | J12: 16:46 | K12: 45586 | L12: 13:05
A13: 2124208629 | B13: =VLOOKUP($A13,ANAGRAFICA!$B$1:$G$306,2,FALSE) -> D'ANDREA | C13: =VLOOKUP($A13,ANAGRAFICA!$B$1:$G$306,3,FALSE) -> FERNANDO ANTONIO | D13: =VLOOKUP($A13,ANAGRAFICA!$B$1:$G$306,4,FALSE) -> 758-5 | E13: =VLOOKUP($A13,ANAGRAFICA!$B$1:$G$306,5,FALSE) -> 3272024071 | F13: =VLOOKUP($A13,ANAGRAFICA!$B$1:$G$306,6,FALSE) -> 2024 | G13: 1 | H13: 1 | I13: 45470 | J13: 17:28 | K13: 45475 | L13: 11:30 | M13: GETINGE HU35 | N13: NA | O13: NA
A14: 2124006081 | B14: =VLOOKUP($A14,ANAGRAFICA!$B$1:$G$306,2,FALSE) -> DOSSI | C14: =VLOOKUP($A14,ANAGRAFICA!$B$1:$G$306,3,FALSE) -> MAURIZIO ANTONIO | D14: =VLOOKUP($A14,ANAGRAFICA!$B$1:$G$306,4,FALSE) | E14: =VLOOKUP($A14,ANAGRAFICA!$B$1:$G$306,5,FALSE) -> 3272024062 | F14: =VLOOKUP($A14,ANAGRAFICA!$B$1:$G$306,6,FALSE) -> 2024 | G14: 1 | H14: 1 | I14: 45387 | J14: 22:30 | K14: 45394 | L14: 15:45 | M14: GETINGE HU35 | N14: NA | O14: NA
A15: 2124025195 | B15: =VLOOKUP($A15,ANAGRAFICA!$B$1:$G$306,2,FALSE) -> FAZIO | C15: =VLOOKUP($A15,ANAGRAFICA!$B$1:$G$306,3,FALSE) -> FRANCESCO ANTONIO | D15: =VLOOKUP($A15,ANAGRAFICA!$B$1:$G$306,4,FALSE) -> 758-21 | E15: =VLOOKUP($A15,ANAGRAFICA!$B$1:$G$306,5,FALSE) -> 3272024087 | F15: =VLOOKUP($A15,ANAGRAFICA!$B$1:$G$306,6,FALSE) -> 2024 | H15: 1 | I15: 45631 | J15: 23:59 | K15: 45638 | L15: 16:24 | M15: GETINGE HU35 | N15: NA | O15: NA
A16: 2124208975 | B16: =VLOOKUP($A16,ANAGRAFICA!$B$1:$G$306,2,FALSE) -> FERRARO | C16: =VLOOKUP($A16,ANAGRAFICA!$B$1:$G$306,3,FALSE) -> DANIELE | D16: =VLOOKUP($A16,ANAGRAFICA!$B$1:$G$306,4,FALSE) | E16: =VLOOKUP($A16,ANAGRAFICA!$B$1:$G$306,5,FALSE) | F16: =VLOOKUP($A16,ANAGRAFICA!$B$1:$G$306,6,FALSE) -> 2024 | H16: 1 | I16: 45483 | J16: 12:27 | K16: 45486 | L16: 16:21
A17: 2124011588 | B17: =VLOOKUP($A17,ANAGRAFICA!$B$1:$G$306,2,FALSE) -> FRATINO | C17: =VLOOKUP($A17,ANAGRAFICA!$B$1:$G$306,3,FALSE) -> OLIVIERO | D17: =VLOOKUP($A17,ANAGRAFICA!$B$1:$G$306,4,FALSE) -> 758-4 | E17: =VLOOKUP($A17,ANAGRAFICA!$B$1:$G$306,5,FALSE) -> 3272024070 | F17: =VLOOKUP($A17,ANAGRAFICA!$B$1:$G$306,6,FALSE) -> 2024 | G17: 1 | H17: 1 | I17: 45462 | J17: 21:00 | K17: 45468 | L17: 01:00 | M17: GETINGE HU35 | N17: NA | O17: NA
A18: 2124014461 | B18: =VLOOKUP($A18,ANAGRAFICA!$B$1:$G$306,2,FALSE) -> FUMAGALLI | C18: =VLOOKUP($A18,ANAGRAFICA!$B$1:$G$306,3,FALSE) -> LUCA | D18: =VLOOKUP($A18,ANAGRAFICA!$B$1:$G$306,4,FALSE) -> 758-10 | E18: =VLOOKUP($A18,ANAGRAFICA!$B$1:$G$306,5,FALSE) -> 3272024076 | F18: =VLOOKUP($A18,ANAGRAFICA!$B$1:$G$306,6,FALSE) -> 2024 | G18: 1 | H18: 1 | I18: 45524 | J18: 21:14:00 | K18: 45534 | L18: 15:30 | M18: GETINGE HU35 | N18: GETINGE PLS SET | O18: PLS
A19: 2124008291 | B19: =VLOOKUP($A19,ANAGRAFICA!$B$1:$G$306,2,FALSE) -> FUMAGALLI | C19: =VLOOKUP($A19,ANAGRAFICA!$B$1:$G$306,3,FALSE) -> PIERO | D19: =VLOOKUP($A19,ANAGRAFICA!$B$1:$G$306,4,FALSE) | E19: =VLOOKUP($A19,ANAGRAFICA!$B$1:$G$306,5,FALSE) -> 3272024065 | F19: =VLOOKUP($A19,ANAGRAFICA!$B$1:$G$306,6,FALSE) -> 2024 | G19: 1 | H19: 1 | I19: 45414 | J19: 11:30 | K19: 45416 | L19: 11:05 | M19: GETINGE HU35 | N19: GETINGE PLS SET | O19: PLS
A20: 2124012915 | B20: =VLOOKUP($A20,ANAGRAFICA!$B$1:$G$306,2,FALSE) -> GARGIONI | C20: =VLOOKUP($A20,ANAGRAFICA!$B$1:$G$306,3,FALSE) -> GIULIO | D20: =VLOOKUP($A20,ANAGRAFICA!$B$1:$G$306,4,FALSE) -> 758-6 | E20: =VLOOKUP($A20,ANAGRAFICA!$B$1:$G$306,5,FALSE) -> 3272024072 | F20: =VLOOKUP($A20,ANAGRAFICA!$B$1:$G$306,6,FALSE) -> 2024 | G20: 1 | H20: 1 | I20: 45485 | J20: 20:56 | K20: 45492 | L20: 16:00 | M20: GETINGE HU35 | N20: NA | O20: NA
A21: 2124000241 | B21: =VLOOKUP($A21,ANAGRAFICA!$B$1:$G$306,2,FALSE) -> ISELLA | C21: =VLOOKUP($A21,ANAGRAFICA!$B$1:$G$306,3,FALSE) -> VINCENZO | D21: =VLOOKUP($A21,ANAGRAFICA!$B$1:$G$306,4,FALSE) | E21: =VLOOKUP($A21,ANAGRAFICA!$B$1:$G$306,5,FALSE) -> 3272024052 | F21: =VLOOKUP($A21,ANAGRAFICA!$B$1:$G$306,6,FALSE) -> 2024 | G21: 1 | H21: 1 | I21: 45296 | J21: 11:53 | K21: 45297 | L21: 09:00 | M21: GETINGE HU35 | N21: n/a | O21: n/a
A22: 2124000328 | B22: =VLOOKUP($A22,ANAGRAFICA!$B$1:$G$306,2,FALSE) -> LAVANGA | C22: =VLOOKUP($A22,ANAGRAFICA!$B$1:$G$306,3,FALSE) -> DONATO | D22: =VLOOKUP($A22,ANAGRAFICA!$B$1:$G$306,4,FALSE) | E22: =VLOOKUP($A22,ANAGRAFICA!$B$1:$G$306,5,FALSE) -> 3272024053 | F22: =VLOOKUP($A22,ANAGRAFICA!$B$1:$G$306,6,FALSE) -> 2024 | G22: 1 | H22: 1 | I22: 45298 | J22: 15:35 | K22: 45301 | L22: 00:00 | M22: GETINGE HU35 | N22: n/a | O22: n/a
A23: 2124008603 | B23: =VLOOKUP($A23,ANAGRAFICA!$B$1:$G$306,2,FALSE) -> MARIANI | C23: =VLOOKUP($A23,ANAGRAFICA!$B$1:$G$306,3,FALSE) -> MARCO | D23: =VLOOKUP($A23,ANAGRAFICA!$B$1:$G$306,4,FALSE) | E23: =VLOOKUP($A23,ANAGRAFICA!$B$1:$G$306,5,FALSE) -> 3272024066 | F23: =VLOOKUP($A23,ANAGRAFICA!$B$1:$G$306,6,FALSE) -> 2024 | G23: 1 | H23: 2 | I23: 45425 | J23: 13:28 | K23: 45447 | L23: 15:30 | M23: GETINGE HU35 | N23: GETINGE HLS SET | O23: HLS
A24: 2124023603 | B24: =VLOOKUP($A24,ANAGRAFICA!$B$1:$G$306,2,FALSE) -> MAZZARDIS | C24: =VLOOKUP($A24,ANAGRAFICA!$B$1:$G$306,3,FALSE) -> DAVIDE | D24: =VLOOKUP($A24,ANAGRAFICA!$B$1:$G$306,4,FALSE) -> 758-19 | E24: =VLOOKUP($A24,ANAGRAFICA!$B$1:$G$306,5,FALSE) -> 3272024085 | F24: =VLOOKUP($A24,ANAGRAFICA!$B$1:$G$306,6,FALSE) -> 2024 | G24: 1 | H24: 1 | I24: 45622 | J24: 12:06 | K24: 45627 | L24: 15:30 | M24: GETINGE HU35 | N24: GETINGE HLS SET | O24: HLS
A25: 2124000149 | B25: =VLOOKUP($A25,ANAGRAFICA!$B$1:$G$306,2,FALSE) -> MOTTA | C25: =VLOOKUP($A25,ANAGRAFICA!$B$1:$G$306,3,FALSE) -> FABIO | D25: =VLOOKUP($A25,ANAGRAFICA!$B$1:$G$306,4,FALSE) | E25: =VLOOKUP($A25,ANAGRAFICA!$B$1:$G$306,5,FALSE) -> 3272024051 | F25: =VLOOKUP($A25,ANAGRAFICA!$B$1:$G$306,6,FALSE) -> 2024 | G25: 1 | H25: 1 | I25: 45295 | J25: 15:55:00 | K25: 45299 | L25: 10:30:00 | M25: GETINGE HU35 | N25: GETINGE PLS SET | O25: PLS
A26: 2124003924 | B26: =VLOOKUP($A26,ANAGRAFICA!$B$1:$G$306,2,FALSE) -> MUHAMMAD | C26: =VLOOKUP($A26,ANAGRAFICA!$B$1:$G$306,3,FALSE) -> SHARIF | D26: =VLOOKUP($A26,ANAGRAFICA!$B$1:$G$306,4,FALSE) | E26: =VLOOKUP($A26,ANAGRAFICA!$B$1:$G$306,5,FALSE) -> 3272024059 | F26: =VLOOKUP($A26,ANAGRAFICA!$B$1:$G$306,6,FALSE) -> 2024 | G26: 1 | H26: 1 | I26: 45349 | J26: 11:39 | K26: 45350 | L26: 15:40 | M26: GETINGE HU35 | N26: GETINGE PLS SET | O26: PLS
A27: 2124010700 | B27: =VLOOKUP($A27,ANAGRAFICA!$B$1:$G$306,2,FALSE) -> ORNAGHI | C27: =VLOOKUP($A27,ANAGRAFICA!$B$1:$G$306,3,FALSE) -> LORENZO | D27: =VLOOKUP($A27,ANAGRAFICA!$B$1:$G$306,4,FALSE) -> 758-2 | E27: =VLOOKUP($A27,ANAGRAFICA!$B$1:$G$306,5,FALSE) -> 3272024068 | F27: =VLOOKUP($A27,ANAGRAFICA!$B$1:$G$306,6,FALSE) -> 2024 | G27: 1 | H27: 1 | I27: 45448 | J27: 14:47 | K27: 45450 | L27: 10:15 | M27: GETINGE HU35 | N27: GETINGE PLS SET | O27: PLS
A28: 2124025878 | B28: =VLOOKUP($A28,ANAGRAFICA!$B$1:$G$306,2,FALSE) -> PEDRONI | C28: =VLOOKUP($A28,ANAGRAFICA!$B$1:$G$306,3,FALSE) -> PIERANGELO | D28: =VLOOKUP($A28,ANAGRAFICA!$B$1:$G$306,4,FALSE) -> 758-22 | E28: =VLOOKUP($A28,ANAGRAFICA!$B$1:$G$306,5,FALSE) -> 3272024088 | F28: =VLOOKUP($A28,ANAGRAFICA!$B$1:$G$306,6,FALSE) -> 2024 | H28: 1 | I28: 45636 | J28: 20:10 | K28: 45644 | L28: 11:32 | M28: GETINGE HU35 | N28: GETINGE HLS SET | O28: HLS | P28: Coagulopathy of unknown source
A29: 2124025878 | B29: =VLOOKUP($A29,ANAGRAFICA!$B$1:$G$306,2,FALSE) -> PEDRONI | C29: =VLOOKUP($A29,ANAGRAFICA!$B$1:$G$306,3,FALSE) -> PIERANGELO | D29: =VLOOKUP($A29,ANAGRAFICA!$B$1:$G$306,4,FALSE) -> 758-22 | E29: =VLOOKUP($A29,ANAGRAFICA!$B$1:$G$306,5,FALSE) -> 3272024088 | F29: =VLOOKUP($A29,ANAGRAFICA!$B$1:$G$306,6,FALSE) -> 2024 | H29: 2 | I29: 45644 | J29: 11:33 | K29: 45645 | L29: 16:10 | M29: GETINGE HU35 | N29: GETINGE HLS SET | O29: HLS
A30: 2124014334 | B30: =VLOOKUP($A30,ANAGRAFICA!$B$1:$G$306,2,FALSE) -> PONTIGGIA | C30: =VLOOKUP($A30,ANAGRAFICA!$B$1:$G$306,3,FALSE) -> FLAVIO | D30: =VLOOKUP($A30,ANAGRAFICA!$B$1:$G$306,4,FALSE) -> 758-9 | E30: =VLOOKUP($A30,ANAGRAFICA!$B$1:$G$306,5,FALSE) -> 3272024075 | F30: =VLOOKUP($A30,ANAGRAFICA!$B$1:$G$306,6,FALSE) -> 2024 | G30: 1 | H30: 1 | I30: 45512 | J30: 11:42 | K30: 45574 | L30: 18:55 | M30: GETINGE HU35 | N30: GETINGE PLS SET | O30: PLS
A31: 2124003531 | B31: =VLOOKUP($A31,ANAGRAFICA!$B$1:$G$306,2,FALSE) -> RASPANTI | C31: =VLOOKUP($A31,ANAGRAFICA!$B$1:$G$306,3,FALSE) -> ANDREA | D31: =VLOOKUP($A31,ANAGRAFICA!$B$1:$G$306,4,FALSE) | E31: =VLOOKUP($A31,ANAGRAFICA!$B$1:$G$306,5,FALSE) -> 3272024057 | F31: =VLOOKUP($A31,ANAGRAFICA!$B$1:$G$306,6,FALSE) -> 2024 | G31: 1 | H31: 1 | I31: 45343 | J31: 18:05 | K31: 45351 | L31: 12:00 | M31: GETINGE HU35 | N31: n/a | O31: n/a
A32: 2124024078 | B32: =VLOOKUP($A32,ANAGRAFICA!$B$1:$G$306,2,FALSE) -> ROVARIS | C32: =VLOOKUP($A32,ANAGRAFICA!$B$1:$G$306,3,FALSE) -> ANGELO FELICE | D32: =VLOOKUP($A32,ANAGRAFICA!$B$1:$G$306,4,FALSE) -> 758-20 | E32: =VLOOKUP($A32,ANAGRAFICA!$B$1:$G$306,5,FALSE) -> 3272024086 | F32: =VLOOKUP($A32,ANAGRAFICA!$B$1:$G$306,6,FALSE) -> 2024 | G32: 1 | H32: 1 | I32: 45625 | J32: 19:50 | K32: 45632 | L32: 14:00 | M32: GETINGE HU35 | N32: GETINGE HLS SET | O32: HLS
A33: 2124005780 | B33: =VLOOKUP($A33,ANAGRAFICA!$B$1:$G$306,2,FALSE) -> SAINCIUC | C33: =VLOOKUP($A33,ANAGRAFICA!$B$1:$G$306,3,FALSE) -> AUREL | D33: =VLOOKUP($A33,ANAGRAFICA!$B$1:$G$306,4,FALSE) | E33: =VLOOKUP($A33,ANAGRAFICA!$B$1:$G$306,5,FALSE) -> 3272024061 | F33: =VLOOKUP($A33,ANAGRAFICA!$B$1:$G$306,6,FALSE) -> 2024 | G33: 1 | H33: 1 | I33: 45376 | J33: 03:45 | K33: 45378 | L33: 04:46 | M33: GETINGE HU35 | N33: GETINGE PLS SET | O33: PLS
A34: 2124017757 | B34: =VLOOKUP($A34,ANAGRAFICA!$B$1:$G$306,2,FALSE) -> SALA | C34: =VLOOKUP($A34,ANAGRAFICA!$B$1:$G$306,3,FALSE) -> FELICE | D34: =VLOOKUP($A34,ANAGRAFICA!$B$1:$G$306,4,FALSE) -> 758-14 | E34: =VLOOKUP($A34,ANAGRAFICA!$B$1:$G$306,5,FALSE) -> 3272024080 | F34: =VLOOKUP($A34,ANAGRAFICA!$B$1:$G$306,6,FALSE) -> 2024 | G34: 1 | H34: 1 | I34: 45572 | J34: 08:15 | K34: 45576 | L34: 13:45 | M34: GETINGE HU35 | N34: N/A | O34: N/A
A35: 2124015827 | B35: =VLOOKUP($A35,ANAGRAFICA!$B$1:$G$306,2,FALSE) -> SCHIAVON | C35: =VLOOKUP($A35,ANAGRAFICA!$B$1:$G$306,3,FALSE) -> ELIO PAOLO | D35: =VLOOKUP($A35,ANAGRAFICA!$B$1:$G$306,4,FALSE) -> 758-11 | E35: =VLOOKUP($A35,ANAGRAFICA!$B$1:$G$306,5,FALSE) -> 3272024077 | F35: =VLOOKUP($A35,ANAGRAFICA!$B$1:$G$306,6,FALSE) -> 2024 | G35: 1 | H35: 1 | I35: 45543 | J35: 16:55 | K35: 45547 | L35: 10:00 | M35: GETINGE HU35 | N35: GETINGE PLS SET | O35: PLS
A36: 2124002215 | B36: =VLOOKUP($A36,ANAGRAFICA!$B$1:$G$306,2,FALSE) -> SCHIFANO | C36: =VLOOKUP($A36,ANAGRAFICA!$B$1:$G$306,3,FALSE) -> FRANCESCO | D36: =VLOOKUP($A36,ANAGRAFICA!$B$1:$G$306,4,FALSE) | E36: =VLOOKUP($A36,ANAGRAFICA!$B$1:$G$306,5,FALSE) -> 3272024055 | F36: =VLOOKUP($A36,ANAGRAFICA!$B$1:$G$306,6,FALSE) -> 2024 | G36: 1 | H36: 1 | I36: 191422 | J36: 13:45 | K36: 45329 | L36: 13:00 | M36: GETINGE HU35 | N36: n/a | O36: n/a
A37: 2124019184 | B37: =VLOOKUP($A37,ANAGRAFICA!$B$1:$G$306,2,FALSE) -> SERVIDIO | C37: =VLOOKUP($A37,ANAGRAFICA!$B$1:$G$306,3,FALSE) -> GIOVANNI | D37: =VLOOKUP($A37,ANAGRAFICA!$B$1:$G$306,4,FALSE) -> 758-17 | E37: =VLOOKUP($A37,ANAGRAFICA!$B$1:$G$306,5,FALSE) -> 3272024083 | F37: =VLOOKUP($A37,ANAGRAFICA!$B$1:$G$306,6,FALSE) -> 2024 | G37: 1 | H37: 1 | I37: 45594 | J37: 16:30 | K37: 45607 | L37: 10:30 | M37: GETINGE HU35 | N37: GETINGE PLS SET | O37: PLS
A38: 2124019184 | B38: =VLOOKUP($A38,ANAGRAFICA!$B$1:$G$306,2,FALSE) -> SERVIDIO | C38: =VLOOKUP($A38,ANAGRAFICA!$B$1:$G$306,3,FALSE) -> GIOVANNI | D38: =VLOOKUP($A38,ANAGRAFICA!$B$1:$G$306,4,FALSE) -> 758-17 | E38: =VLOOKUP($A38,ANAGRAFICA!$B$1:$G$306,5,FALSE) -> 3272024083 | F38: =VLOOKUP($A38,ANAGRAFICA!$B$1:$G$306,6,FALSE) -> 2024 | G38: 1 | H38: 2 | I38: 45607 | J38: 10:30 | K38: 45611 | L38: 11:00 | M38: GETINGE HU35 | N38: EUROSETS
A39: 2124013801 | B39: =VLOOKUP($A39,ANAGRAFICA!$B$1:$G$306,2,FALSE) -> SGOBBA | C39: =VLOOKUP($A39,ANAGRAFICA!$B$1:$G$306,3,FALSE) -> ANNA | D39: =VLOOKUP($A39,ANAGRAFICA!$B$1:$G$306,4,FALSE) -> 758-8 | E39: =VLOOKUP($A39,ANAGRAFICA!$B$1:$G$306,5,FALSE) -> 3272024074 | F39: =VLOOKUP($A39,ANAGRAFICA!$B$1:$G$306,6,FALSE) -> 2024 | G39: 1 | H39: 1 | I39: 45511 | J39: 15:30 | K39: 45520 | L39: 18:00 | M39: GETINGE HU35 | N39: GETINGE PLS SET | O39: PLS
A40: 2125000348 | B40: =VLOOKUP($A40,ANAGRAFICA!$B$1:$G$306,2,FALSE) -> SLAVKOVA | C40: =VLOOKUP($A40,ANAGRAFICA!$B$1:$G$306,3,FALSE) -> EVELINA PLAMENOVA | D40: =VLOOKUP($A40,ANAGRAFICA!$B$1:$G$306,4,FALSE) | E40: =VLOOKUP($A40,ANAGRAFICA!$B$1:$G$306,5,FALSE) -> 3272025051 | F40: =VLOOKUP($A40,ANAGRAFICA!$B$1:$G$306,6,FALSE) -> 2025 | H40: 1 | I40: 45662 | J40: 22:35 | K40: 45665 | L40: 3:00 | M40: GETINGE HU35 | N40: GETINGE HLS SET | O40: HLS
...

Sheet DIAGNOSI
A1: SDO | B1: COGNOME | C1: NOME | D1: ECMO LENS | E1: ELSO | F1: ANNO | G1: RUN | H1: DIAGNOSI PRINCIPALE | I1: DIAGNOSI 2 | J1: DIAGNOSI 3 | K1: DIAGNOSI 4 | L1: AIM
A2: 2124012963 | B2: =VLOOKUP($A2,ANAGRAFICA!$B$1:$G$306,2,FALSE) -> TARENZI | C2: =VLOOKUP($A2,ANAGRAFICA!$B$1:$G$306,3,FALSE) -> GIACOMO | D2: =VLOOKUP($A2,ANAGRAFICA!$B$1:$G$306,4,FALSE) -> 758-7 | E2: =VLOOKUP($A2,ANAGRAFICA!$B$1:$G$306,5,FALSE) -> 3272024073 | F2: =VLOOKUP($A2,ANAGRAFICA!$B$1:$G$306,6,FALSE) -> 2024 | G2: 1 | H2: I46.9 Arresto cardiaco non specificato | I2: I26.0 Embolia polmonare con menzione di cuore polmonare acuto | L2: ECPR
A3: 2124019725 | B3: =VLOOKUP($A3,ANAGRAFICA!$B$1:$G$306,2,FALSE) -> AMIWO | C3: =VLOOKUP($A3,ANAGRAFICA!$B$1:$G$306,3,FALSE) -> REX STEVE | D3: =VLOOKUP($A3,ANAGRAFICA!$B$1:$G$306,4,FALSE) -> 758-18 | E3: =VLOOKUP($A3,ANAGRAFICA!$B$1:$G$306,5,FALSE) -> 3272024084 | F3: =VLOOKUP($A3,ANAGRAFICA!$B$1:$G$306,6,FALSE) -> 2024 | G3: 1 | H3: R57.0 Shock cardiogeno | I3: R57.8 Altre forme di shock | L3: CARDIAC
A4: 2123023299 | B4: =VLOOKUP($A4,ANAGRAFICA!$B$1:$G$306,2,FALSE) -> BEATRICE | C4: =VLOOKUP($A4,ANAGRAFICA!$B$1:$G$306,3,FALSE) -> GERARDINA | D4: =VLOOKUP($A4,ANAGRAFICA!$B$1:$G$306,4,FALSE) | E4: =VLOOKUP($A4,ANAGRAFICA!$B$1:$G$306,5,FALSE) -> 3272024098 | F4: =VLOOKUP($A4,ANAGRAFICA!$B$1:$G$306,6,FALSE) -> 2024 | G4: 1 | H4: I46.9 Arresto cardiaco non specificato | I4: R57.0 Shock cardiogeno | J4: R57.8 Altre forme di shock | L4: ECPR
A5: 2124011236 | B5: =VLOOKUP($A5,ANAGRAFICA!$B$1:$G$306,2,FALSE) -> BERETTA | C5: =VLOOKUP($A5,ANAGRAFICA!$B$1:$G$306,3,FALSE) -> ENZO LUCIANO | D5: =VLOOKUP($A5,ANAGRAFICA!$B$1:$G$306,4,FALSE) -> 758-3 | E5: =VLOOKUP($A5,ANAGRAFICA!$B$1:$G$306,5,FALSE) -> 3272024069 | F5: =VLOOKUP($A5,ANAGRAFICA!$B$1:$G$306,6,FALSE) -> 2024 | G5: 1 | H5: I46.0 Arresto cardiaco con efficace rianimazione | L5: CARDIAC
A6: 2124000241 | B6: =VLOOKUP($A6,ANAGRAFICA!$B$1:$G$306,2,FALSE) -> ISELLA | C6: =VLOOKUP($A6,ANAGRAFICA!$B$1:$G$306,3,FALSE) -> VINCENZO | D6: =VLOOKUP($A6,ANAGRAFICA!$B$1:$G$306,4,FALSE) | E6: =VLOOKUP($A6,ANAGRAFICA!$B$1:$G$306,5,FALSE) -> 3272024052 | F6: =VLOOKUP($A6,ANAGRAFICA!$B$1:$G$306,6,FALSE) -> 2024 | G6: 1 | H6: I46.9 Arresto cardiaco non specificato | I6: R57.0 Shock cardiogeno | L6: ECPR
A7: 2124000328 | B7: =VLOOKUP($A7,ANAGRAFICA!$B$1:$G$306,2,FALSE) -> LAVANGA | C7: =VLOOKUP($A7,ANAGRAFICA!$B$1:$G$306,3,FALSE) -> DONATO | D7: =VLOOKUP($A7,ANAGRAFICA!$B$1:$G$306,4,FALSE) | E7: =VLOOKUP($A7,ANAGRAFICA!$B$1:$G$306,5,FALSE) -> 3272024053 | F7: =VLOOKUP($A7,ANAGRAFICA!$B$1:$G$306,6,FALSE) -> 2024 | G7: 1 | H7: I46.9 Arresto cardiaco non specificato | I7: I51.9 Cardiopatia non specificata | L7: ECPR
A8: 2124001121 | B8: =VLOOKUP($A8,ANAGRAFICA!$B$1:$G$306,2,FALSE) -> TIEGHI | C8: =VLOOKUP($A8,ANAGRAFICA!$B$1:$G$306,3,FALSE) -> MASSIMO | D8: =VLOOKUP($A8,ANAGRAFICA!$B$1:$G$306,4,FALSE) | E8: =VLOOKUP($A8,ANAGRAFICA!$B$1:$G$306,5,FALSE) -> 3272024054 | F8: =VLOOKUP($A8,ANAGRAFICA!$B$1:$G$306,6,FALSE) -> 2024 | G8: 1 | H8: I21.0 Infarto miocardico acuto transmurale della parete anteriore | I8: I46.9 Arresto cardiaco non specificato | L8: ECPR
A9: 2124203781 | B9: =VLOOKUP($A9,ANAGRAFICA!$B$1:$G$306,2,FALSE) -> CONCA | C9: =VLOOKUP($A9,ANAGRAFICA!$B$1:$G$306,3,FALSE) -> CAMILLA | D9: =VLOOKUP($A9,ANAGRAFICA!$B$1:$G$306,4,FALSE) | E9: =VLOOKUP($A9,ANAGRAFICA!$B$1:$G$306,5,FALSE) -> 3272024058 | F9: =VLOOKUP($A9,ANAGRAFICA!$B$1:$G$306,6,FALSE) -> 2024 | G9: 1 | H9: Dissection of thoracic aorta,"I71.01" | I9: R57.0 Shock cardiogeno | L9: CARDIAC
A10: 2124206072 | B10: =VLOOKUP($A10,ANAGRAFICA!$B$1:$G$306,2,FALSE) -> CONSONNI | C10: =VLOOKUP($A10,ANAGRAFICA!$B$1:$G$306,3,FALSE) -> GIULIO | D10: =VLOOKUP($A10,ANAGRAFICA!$B$1:$G$306,4,FALSE) | E10: =VLOOKUP($A10,ANAGRAFICA!$B$1:$G$306,5,FALSE) -> 3272024064 | F10: =VLOOKUP($A10,ANAGRAFICA!$B$1:$G$306,6,FALSE) -> 2024 | G10: 1 | H10: R57.0 Shock cardiogeno | I10: Dissection of thoracic aorta,"I71.01" | J10: I46.0 Arresto cardiaco con efficace rianimazione | L10: CARDIAC
A11: 2124202869 | B11: =VLOOKUP($A11,ANAGRAFICA!$B$1:$G$306,2,FALSE) -> VALSECCHI | C11: =VLOOKUP($A11,ANAGRAFICA!$B$1:$G$306,3,FALSE) -> ANDREA | D11: =VLOOKUP($A11,ANAGRAFICA!$B$1:$G$306,4,FALSE) | E11: =VLOOKUP($A11,ANAGRAFICA!$B$1:$G$306,5,FALSE) -> 3272024056 | F11: =VLOOKUP($A11,ANAGRAFICA!$B$1:$G$306,6,FALSE) -> 2024 | G11: 1 | H11: I21.2 Infarto miocardico acuto transmurale di altre sedi | I11: R57.0 Shock cardiogeno | J11: I46.9 Arresto cardiaco non specificato | L11: ECPR
A12: 2124206072 | B12: =VLOOKUP($A12,ANAGRAFICA!$B$1:$G$306,2,FALSE) -> CONSONNI | C12: =VLOOKUP($A12,ANAGRAFICA!$B$1:$G$306,3,FALSE) -> GIULIO | D12: =VLOOKUP($A12,ANAGRAFICA!$B$1:$G$306,4,FALSE) | E12: =VLOOKUP($A12,ANAGRAFICA!$B$1:$G$306,5,FALSE) -> 3272024064 | F12: =VLOOKUP($A12,ANAGRAFICA!$B$1:$G$306,6,FALSE) -> 2024 | G12: 2 | H12: I44.2 Blocco atrioventricolare completo | L12: CARDIAC
A13: 2124211722 | B13: =VLOOKUP($A13,ANAGRAFICA!$B$1:$G$306,2,FALSE) -> CORIO | C13: =VLOOKUP($A13,ANAGRAFICA!$B$1:$G$306,3,FALSE) -> GIOVANNI | D13: =VLOOKUP($A13,ANAGRAFICA!$B$1:$G$306,4,FALSE) -> 758-13 | E13: =VLOOKUP($A13,ANAGRAFICA!$B$1:$G$306,5,FALSE) -> 3272024079 | F13: =VLOOKUP($A13,ANAGRAFICA!$B$1:$G$306,6,FALSE) -> 2024 | G13: 1 | H13: I21.0 Infarto miocardico acuto transmurale della parete anteriore | I13: R57.0 Shock cardiogeno | L13: CARDIAC
A14: 2124018611 | B14: =VLOOKUP($A14,ANAGRAFICA!$B$1:$G$306,2,FALSE) -> CURTO | C14: =VLOOKUP($A14,ANAGRAFICA!$B$1:$G$306,3,FALSE) -> ROBERTO | D14: =VLOOKUP($A14,ANAGRAFICA!$B$1:$G$306,4,FALSE) | E14: =VLOOKUP($A14,ANAGRAFICA!$B$1:$G$306,5,FALSE) | F14: =VLOOKUP($A14,ANAGRAFICA!$B$1:$G$306,6,FALSE) -> 2024 | G14: 1 | H14: R57.0 Shock cardiogeno | L14: CARDIAC
A15: 2124018690 | B15: =VLOOKUP($A15,ANAGRAFICA!$B$1:$G$306,2,FALSE) -> AVENIDO | C15: =VLOOKUP($A15,ANAGRAFICA!$B$1:$G$306,3,FALSE) -> DELFIN | D15: =VLOOKUP($A15,ANAGRAFICA!$B$1:$G$306,4,FALSE) -> 758-16 | E15: =VLOOKUP($A15,ANAGRAFICA!$B$1:$G$306,5,FALSE) -> 3272024082 | F15: =VLOOKUP($A15,ANAGRAFICA!$B$1:$G$306,6,FALSE) -> 2024 | G15: 1 | H15: I46.0 Arresto cardiaco con efficace rianimazione | L15: ECPR
A16: 2124018637 | B16: =VLOOKUP($A16,ANAGRAFICA!$B$1:$G$306,2,FALSE) -> CARIBONI | C16: =VLOOKUP($A16,ANAGRAFICA!$B$1:$G$306,3,FALSE) -> LORENZA | D16: =VLOOKUP($A16,ANAGRAFICA!$B$1:$G$306,4,FALSE) -> 758-15 | E16: =VLOOKUP($A16,ANAGRAFICA!$B$1:$G$306,5,FALSE) -> 3272024081 | F16: =VLOOKUP($A16,ANAGRAFICA!$B$1:$G$306,6,FALSE) -> 2024 | G16: 1 | H16: I46.0 Arresto cardiaco con efficace rianimazione | I16: I21.0 Infarto miocardico acuto transmurale della parete anteriore | J16: R57.0 Shock cardiogeno | L16: ECPR
A17: 2124006081 | B17: =VLOOKUP($A17,ANAGRAFICA!$B$1:$G$306,2,FALSE) -> DOSSI | C17: =VLOOKUP($A17,ANAGRAFICA!$B$1:$G$306,3,FALSE) -> MAURIZIO ANTONIO | D17: =VLOOKUP($A17,ANAGRAFICA!$B$1:$G$306,4,FALSE) | E17: =VLOOKUP($A17,ANAGRAFICA!$B$1:$G$306,5,FALSE) -> 3272024062 | F17: =VLOOKUP($A17,ANAGRAFICA!$B$1:$G$306,6,FALSE) -> 2024 | G17: 1 | H17: R57.0 Shock cardiogeno | L17: CARDIAC
A18: 2124025195 | B18: =VLOOKUP($A18,ANAGRAFICA!$B$1:$G$306,2,FALSE) -> FAZIO | C18: =VLOOKUP($A18,ANAGRAFICA!$B$1:$G$306,3,FALSE) -> FRANCESCO ANTONIO | D18: =VLOOKUP($A18,ANAGRAFICA!$B$1:$G$306,4,FALSE) -> 758-21 | E18: =VLOOKUP($A18,ANAGRAFICA!$B$1:$G$306,5,FALSE) -> 3272024087 | F18: =VLOOKUP($A18,ANAGRAFICA!$B$1:$G$306,6,FALSE) -> 2024 | G18: 1 | H18: I46.0 Arresto cardiaco con efficace rianimazione | I18: I21.0 Infarto miocardico acuto transmurale della parete anteriore | L18: ECPR
A19: 2124208975 | B19: =VLOOKUP($A19,ANAGRAFICA!$B$1:$G$306,2,FALSE) -> FERRARO | C19: =VLOOKUP($A19,ANAGRAFICA!$B$1:$G$306,3,FALSE) -> DANIELE | D19: =VLOOKUP($A19,ANAGRAFICA!$B$1:$G$306,4,FALSE) | E19: =VLOOKUP($A19,ANAGRAFICA!$B$1:$G$306,5,FALSE) | F19: =VLOOKUP($A19,ANAGRAFICA!$B$1:$G$306,6,FALSE) -> 2024 | G19: 1 | H19: Dissection of thoracic aorta,"I71.01" | I19: R57.0 Shock cardiogeno | L19: CARDIAC
A20: 2124014334 | B20: =VLOOKUP($A20,ANAGRAFICA!$B$1:$G$306,2,FALSE) -> PONTIGGIA | C20: =VLOOKUP($A20,ANAGRAFICA!$B$1:$G$306,3,FALSE) -> FLAVIO | D20: =VLOOKUP($A20,ANAGRAFICA!$B$1:$G$306,4,FALSE) -> 758-9 | E20: =VLOOKUP($A20,ANAGRAFICA!$B$1:$G$306,5,FALSE) -> 3272024075 | F20: =VLOOKUP($A20,ANAGRAFICA!$B$1:$G$306,6,FALSE) -> 2024 | G20: 1 | H20: I46.0 Arresto cardiaco con efficace rianimazione | L20: ECPR
A21: 2124011588 | B21: =VLOOKUP($A21,ANAGRAFICA!$B$1:$G$306,2,FALSE) -> FRATINO | C21: =VLOOKUP($A21,ANAGRAFICA!$B$1:$G$306,3,FALSE) -> OLIVIERO | D21: =VLOOKUP($A21,ANAGRAFICA!$B$1:$G$306,4,FALSE) -> 758-4 | E21: =VLOOKUP($A21,ANAGRAFICA!$B$1:$G$306,5,FALSE) -> 3272024070 | F21: =VLOOKUP($A21,ANAGRAFICA!$B$1:$G$306,6,FALSE) -> 2024 | G21: 1 | H21: I21.0 Infarto miocardico acuto transmurale della parete anteriore | I21: R57.0 Shock cardiogeno | L21: CARDIAC
A22: 2124012915 | B22: =VLOOKUP($A22,ANAGRAFICA!$B$1:$G$306,2,FALSE) -> GARGIONI | C22: =VLOOKUP($A22,ANAGRAFICA!$B$1:$G$306,3,FALSE) -> GIULIO | D22: =VLOOKUP($A22,ANAGRAFICA!$B$1:$G$306,4,FALSE) -> 758-6 | E22: =VLOOKUP($A22,ANAGRAFICA!$B$1:$G$306,5,FALSE) -> 3272024072 | F22: =VLOOKUP($A22,ANAGRAFICA!$B$1:$G$306,6,FALSE) -> 2024 | G22: 1 | H22: I46.0 Arresto cardiaco con efficace rianimazione | I22: I21.0 Infarto miocardico acuto transmurale della parete anteriore | L22: ECPR
A23: 2124208629 | B23: =VLOOKUP($A23,ANAGRAFICA!$B$1:$G$306,2,FALSE) -> D'ANDREA | C23: =VLOOKUP($A23,ANAGRAFICA!$B$1:$G$306,3,FALSE) -> FERNANDO ANTONIO | D23: =VLOOKUP($A23,ANAGRAFICA!$B$1:$G$306,4,FALSE) -> 758-5 | E23: =VLOOKUP($A23,ANAGRAFICA!$B$1:$G$306,5,FALSE) -> 3272024071 | F23: =VLOOKUP($A23,ANAGRAFICA!$B$1:$G$306,6,FALSE) -> 2024 | G23: 1 | H23: I46.0 Arresto cardiaco con efficace rianimazione | L23: ECPR
A24: 2124014461 | B24: =VLOOKUP($A24,ANAGRAFICA!$B$1:$G$306,2,FALSE) -> FUMAGALLI | C24: =VLOOKUP($A24,ANAGRAFICA!$B$1:$G$306,3,FALSE) -> LUCA | D24: =VLOOKUP($A24,ANAGRAFICA!$B$1:$G$306,4,FALSE) -> 758-10 | E24: =VLOOKUP($A24,ANAGRAFICA!$B$1:$G$306,5,FALSE) -> 3272024076 | F24: =VLOOKUP($A24,ANAGRAFICA!$B$1:$G$306,6,FALSE) -> 2024 | G24: 1 | H24: R57.0 Shock cardiogeno | L24: CARDIAC
A25: 2124008291 | B25: =VLOOKUP($A25,ANAGRAFICA!$B$1:$G$306,2,FALSE) -> FUMAGALLI | C25: =VLOOKUP($A25,ANAGRAFICA!$B$1:$G$306,3,FALSE) -> PIERO | D25: =VLOOKUP($A25,ANAGRAFICA!$B$1:$G$306,4,FALSE) | E25: =VLOOKUP($A25,ANAGRAFICA!$B$1:$G$306,5,FALSE) -> 3272024065 | F25: =VLOOKUP($A25,ANAGRAFICA!$B$1:$G$306,6,FALSE) -> 2024 | G25: 1 | H25: R65.21 SHOCK SETTICO | I25: R57.0 Shock cardiogeno | L25: CARDIAC
A26: 2124010700 | B26: =VLOOKUP($A26,ANAGRAFICA!$B$1:$G$306,2,FALSE) -> ORNAGHI | C26: =VLOOKUP($A26,ANAGRAFICA!$B$1:$G$306,3,FALSE) -> LORENZO | D26: =VLOOKUP($A26,ANAGRAFICA!$B$1:$G$306,4,FALSE) -> 758-2 | E26: =VLOOKUP($A26,ANAGRAFICA!$B$1:$G$306,5,FALSE) -> 3272024068 | F26: =VLOOKUP($A26,ANAGRAFICA!$B$1:$G$306,6,FALSE) -> 2024 | G26: 1 | H26: I46.0 Arresto cardiaco con efficace rianimazione | I26: I21.0 Infarto miocardico acuto transmurale della parete anteriore | L26: ECPR
A27: 2124009735 | B27: =VLOOKUP($A27,ANAGRAFICA!$B$1:$G$306,2,FALSE) -> BOSSI | C27: =VLOOKUP($A27,ANAGRAFICA!$B$1:$G$306,3,FALSE) -> LUDOVICO | D27: =VLOOKUP($A27,ANAGRAFICA!$B$1:$G$306,4,FALSE) -> 758-1 | E27: =VLOOKUP($A27,ANAGRAFICA!$B$1:$G$306,5,FALSE) -> 3272024067 | F27: =VLOOKUP($A27,ANAGRAFICA!$B$1:$G$306,6,FALSE) -> 2024 | G27: 1 | H27: I46.0 Arresto cardiaco con efficace rianimazione | I27: I21.0 Infarto miocardico acuto transmurale della parete anteriore | L27: ECPR
A28: 2124008603 | B28: =VLOOKUP($A28,ANAGRAFICA!$B$1:$G$306,2,FALSE) -> MARIANI | C28: =VLOOKUP($A28,ANAGRAFICA!$B$1:$G$306,3,FALSE) -> MARCO | D28: =VLOOKUP($A28,ANAGRAFICA!$B$1:$G$306,4,FALSE) | E28: =VLOOKUP($A28,ANAGRAFICA!$B$1:$G$306,5,FALSE) -> 3272024066 | F28: =VLOOKUP($A28,ANAGRAFICA!$B$1:$G$306,6,FALSE) -> 2024 | G28: 1 | H28: Dissection of thoracoabdominal aorta,"I71.03" | I28: R65.21 SHOCK SETTICO | L28: PULMONARY
A29: 2124000149 | B29: =VLOOKUP($A29,ANAGRAFICA!$B$1:$G$306,2,FALSE) -> MOTTA | C29: =VLOOKUP($A29,ANAGRAFICA!$B$1:$G$306,3,FALSE) -> FABIO | D29: =VLOOKUP($A29,ANAGRAFICA!$B$1:$G$306,4,FALSE) | E29: =VLOOKUP($A29,ANAGRAFICA!$B$1:$G$306,5,FALSE) -> 3272024051 | F29: =VLOOKUP($A29,ANAGRAFICA!$B$1:$G$306,6,FALSE) -> 2024 | G29: 1 | H29: Dissection of thoracoabdominal aorta,"I71.03" | I29: Injury of heart with hemopericardium,"S26.0" | J29: R57.0 Shock cardiogeno | L29: CARDIAC
A30: 2124003924 | B30: =VLOOKUP($A30,ANAGRAFICA!$B$1:$G$306,2,FALSE) -> MUHAMMAD | C30: =VLOOKUP($A30,ANAGRAFICA!$B$1:$G$306,3,FALSE) -> SHARIF | D30: =VLOOKUP($A30,ANAGRAFICA!$B$1:$G$306,4,FALSE) | E30: =VLOOKUP($A30,ANAGRAFICA!$B$1:$G$306,5,FALSE) -> 3272024059 | F30: =VLOOKUP($A30,ANAGRAFICA!$B$1:$G$306,6,FALSE) -> 2024 | G30: 1 | H30: I46.0 Arresto cardiaco con efficace rianimazione | I30: I21.0 Infarto miocardico acuto transmurale della parete anteriore | L30: CARDIAC
A31: 2124025878 | B31: =VLOOKUP($A31,ANAGRAFICA!$B$1:$G$306,2,FALSE) -> PEDRONI | C31: =VLOOKUP($A31,ANAGRAFICA!$B$1:$G$306,3,FALSE) -> PIERANGELO | D31: =VLOOKUP($A31,ANAGRAFICA!$B$1:$G$306,4,FALSE) -> 758-22 | E31: =VLOOKUP($A31,ANAGRAFICA!$B$1:$G$306,5,FALSE) -> 3272024088 | F31: =VLOOKUP($A31,ANAGRAFICA!$B$1:$G$306,6,FALSE) -> 2024 | G31: 1 | H31: I21.0 Infarto miocardico acuto transmurale della parete anteriore | I31: I46.0 Arresto cardiaco con efficace rianimazione | J31: R57.0 Shock cardiogeno | L31: ECPR
A32: 2124007138 | B32: =VLOOKUP($A32,ANAGRAFICA!$B$1:$G$306,2,FALSE) -> TARTARELLI | C32: =VLOOKUP($A32,ANAGRAFICA!$B$1:$G$306,3,FALSE) -> GIUSEPPE | D32: =VLOOKUP($A32,ANAGRAFICA!$B$1:$G$306,4,FALSE) | E32: =VLOOKUP($A32,ANAGRAFICA!$B$1:$G$306,5,FALSE) -> 3272024063 | F32: =VLOOKUP($A32,ANAGRAFICA!$B$1:$G$306,6,FALSE) -> 2024 | G32: 1 | H32: I46.0 Arresto cardiaco con efficace rianimazione | I32: I21.0 Infarto miocardico acuto transmurale della parete anteriore | L32: ECPR
A33: 2124015827 | B33: =VLOOKUP($A33,ANAGRAFICA!$B$1:$G$306,2,FALSE) -> SCHIAVON | C33: =VLOOKUP($A33,ANAGRAFICA!$B$1:$G$306,3,FALSE) -> ELIO PAOLO | D33: =VLOOKUP($A33,ANAGRAFICA!$B$1:$G$306,4,FALSE) -> 758-11 | E33: =VLOOKUP($A33,ANAGRAFICA!$B$1:$G$306,5,FALSE) -> 3272024077 | F33: =VLOOKUP($A33,ANAGRAFICA!$B$1:$G$306,6,FALSE) -> 2024 | G33: 1 | H33: I46.0 Arresto cardiaco con efficace rianimazione | I33: I21.0 Infarto miocardico acuto transmurale della parete anteriore | L33: ECPR
A34: 2124005780 | B34: =VLOOKUP($A34,ANAGRAFICA!$B$1:$G$306,2,FALSE) -> SAINCIUC | C34: =VLOOKUP($A34,ANAGRAFICA!$B$1:$G$306,3,FALSE) -> AUREL | D34: =VLOOKUP($A34,ANAGRAFICA!$B$1:$G$306,4,FALSE) | E34: =VLOOKUP($A34,ANAGRAFICA!$B$1:$G$306,5,FALSE) -> 3272024061 | F34: =VLOOKUP($A34,ANAGRAFICA!$B$1:$G$306,6,FALSE) -> 2024 | G34: 1 | H34: I46.0 Arresto cardiaco con efficace rianimazione | I34: I21.0 Infarto miocardico acuto transmurale della parete anteriore | L34: ECPR
